

=============================================================
Время: 2020-09-01 14:52:17.662701

Ошибка:
Traceback (most recent call last):
  File "C:\Users\ProstoChelovek\AppData\Local\Programs\Python\Python38-32\lib\site-packages\discord\ext\commands\bot.py", line 608, in _load_from_module_spec
    setup(self)
  File "e:\PyProg\ProstoTools\Cogs\different.py", line 445, in setup
    client.add_cog(Different(client))
  File "e:\PyProg\ProstoTools\Cogs\different.py", line 30, in __init__
    self.conn = mysql.connector.connect(user = 'root', password = os.environ['DB_PASSWORD'], host = 'localhost', database = 'data')
NameError: name 'os' is not defined

The above exception was the direct cause of the following exception:

Traceback (most recent call last):
  File "e:/PyProg/ProstoTools/bot.py", line 61, in <module>
    client.load_extension(f'Cogs.{filename[:-3]}')
  File "C:\Users\ProstoChelovek\AppData\Local\Programs\Python\Python38-32\lib\site-packages\discord\ext\commands\bot.py", line 653, in load_extension
    self._load_from_module_spec(spec, name)
  File "C:\Users\ProstoChelovek\AppData\Local\Programs\Python\Python38-32\lib\site-packages\discord\ext\commands\bot.py", line 613, in _load_from_module_spec
    raise errors.ExtensionFailed(key, e) from e
discord.ext.commands.errors.ExtensionFailed: Extension 'Cogs.different' raised an error: NameError: name 'os' is not defined

=============================================================

=============================================================
Время: 2020-09-01 14:52:19.140942

Ошибка:
Traceback (most recent call last):
  File "C:\Users\ProstoChelovek\AppData\Local\Programs\Python\Python38-32\lib\site-packages\discord\ext\commands\bot.py", line 608, in _load_from_module_spec
    setup(self)
  File "e:\PyProg\ProstoTools\Cogs\moderate.py", line 1012, in setup
    client.add_cog(Moderate(client))
  File "e:\PyProg\ProstoTools\Cogs\moderate.py", line 50, in __init__
    self.conn = mysql.connector.connect(user = 'root', password = os.environ['DB_PASSWORD'], host = 'localhost', database = 'data')
NameError: name 'os' is not defined

The above exception was the direct cause of the following exception:

Traceback (most recent call last):
  File "e:/PyProg/ProstoTools/bot.py", line 61, in <module>
    client.load_extension(f'Cogs.{filename[:-3]}')
  File "C:\Users\ProstoChelovek\AppData\Local\Programs\Python\Python38-32\lib\site-packages\discord\ext\commands\bot.py", line 653, in load_extension
    self._load_from_module_spec(spec, name)
  File "C:\Users\ProstoChelovek\AppData\Local\Programs\Python\Python38-32\lib\site-packages\discord\ext\commands\bot.py", line 613, in _load_from_module_spec
    raise errors.ExtensionFailed(key, e) from e
discord.ext.commands.errors.ExtensionFailed: Extension 'Cogs.moderate' raised an error: NameError: name 'os' is not defined

=============================================================

=============================================================
Время: 2020-09-01 14:52:19.191807

Ошибка:
Traceback (most recent call last):
  File "C:\Users\ProstoChelovek\AppData\Local\Programs\Python\Python38-32\lib\site-packages\discord\ext\commands\bot.py", line 608, in _load_from_module_spec
    setup(self)
  File "e:\PyProg\ProstoTools\Cogs\settings.py", line 571, in setup
    client.add_cog(Settings(client))
  File "e:\PyProg\ProstoTools\Cogs\settings.py", line 28, in __init__
    self.conn = mysql.connector.connect(user = 'root', password = os.environ['DB_PASSWORD'], host = 'localhost', database = 'data')
NameError: name 'os' is not defined

The above exception was the direct cause of the following exception:

Traceback (most recent call last):
  File "e:/PyProg/ProstoTools/bot.py", line 61, in <module>
    client.load_extension(f'Cogs.{filename[:-3]}')
  File "C:\Users\ProstoChelovek\AppData\Local\Programs\Python\Python38-32\lib\site-packages\discord\ext\commands\bot.py", line 653, in load_extension
    self._load_from_module_spec(spec, name)
  File "C:\Users\ProstoChelovek\AppData\Local\Programs\Python\Python38-32\lib\site-packages\discord\ext\commands\bot.py", line 613, in _load_from_module_spec
    raise errors.ExtensionFailed(key, e) from e
discord.ext.commands.errors.ExtensionFailed: Extension 'Cogs.settings' raised an error: NameError: name 'os' is not defined

=============================================================

=============================================================
Время: 2020-09-01 14:52:19.211753

Ошибка:
Traceback (most recent call last):
  File "C:\Users\ProstoChelovek\AppData\Local\Programs\Python\Python38-32\lib\site-packages\discord\ext\commands\bot.py", line 608, in _load_from_module_spec
    setup(self)
  File "e:\PyProg\ProstoTools\Cogs\utils.py", line 320, in setup
    client.add_cog(Utils(client))
  File "e:\PyProg\ProstoTools\Cogs\utils.py", line 46, in __init__
    self.conn = mysql.connector.connect(user = 'root', password = os.environ['DB_PASSWORD'], host = 'localhost', database = 'data')
NameError: name 'os' is not defined

The above exception was the direct cause of the following exception:

Traceback (most recent call last):
  File "e:/PyProg/ProstoTools/bot.py", line 61, in <module>
    client.load_extension(f'Cogs.{filename[:-3]}')
  File "C:\Users\ProstoChelovek\AppData\Local\Programs\Python\Python38-32\lib\site-packages\discord\ext\commands\bot.py", line 653, in load_extension
    self._load_from_module_spec(spec, name)
  File "C:\Users\ProstoChelovek\AppData\Local\Programs\Python\Python38-32\lib\site-packages\discord\ext\commands\bot.py", line 613, in _load_from_module_spec
    raise errors.ExtensionFailed(key, e) from e
discord.ext.commands.errors.ExtensionFailed: Extension 'Cogs.utils' raised an error: NameError: name 'os' is not defined

=============================================================

=============================================================
Время: 2020-09-01 14:55:19.926962

Ошибка:
Command "HeLP" is not found
=============================================================

=============================================================
Время: 2020-09-01 14:55:26.827048

Ошибка:
Command "hELP" is not found
=============================================================