

=============================================================
Время: 2020-07-21 13:56:38.748458

Ошибка:
Traceback (most recent call last):
  File "C:\Users\ProstoChelovek\AppData\Local\Programs\Python\Python38-32\lib\site-packages\discord\ext\commands\bot.py", line 596, in _load_from_module_spec
    spec.loader.exec_module(lib)
  File "<frozen importlib._bootstrap_external>", line 783, in exec_module
  File "<frozen importlib._bootstrap>", line 219, in _call_with_frames_removed
  File "E:\PyProg\ProstoTools(Original version)\Cogs\different.py", line 12, in <module>
    from Tools.database import DB
  File "E:\PyProg\ProstoTools(Original version)\Tools\database.py", line 7, in <module>
    cursor.execute("""CREATE TABLE IF NOT EXISTS users(
NameError: name 'cursor' is not defined

The above exception was the direct cause of the following exception:

Traceback (most recent call last):
  File "bot.py", line 75, in <module>
    client.load_extension(f'Cogs.{filename[:-3]}')
  File "C:\Users\ProstoChelovek\AppData\Local\Programs\Python\Python38-32\lib\site-packages\discord\ext\commands\bot.py", line 653, in load_extension
    self._load_from_module_spec(spec, name)
  File "C:\Users\ProstoChelovek\AppData\Local\Programs\Python\Python38-32\lib\site-packages\discord\ext\commands\bot.py", line 599, in _load_from_module_spec
    raise errors.ExtensionFailed(key, e) from e
discord.ext.commands.errors.ExtensionFailed: Extension 'Cogs.different' raised an error: NameError: name 'cursor' is not defined

=============================================================

=============================================================
Время: 2020-07-21 13:56:41.632749

Ошибка:
Traceback (most recent call last):
  File "C:\Users\ProstoChelovek\AppData\Local\Programs\Python\Python38-32\lib\site-packages\discord\ext\commands\bot.py", line 596, in _load_from_module_spec
    spec.loader.exec_module(lib)
  File "<frozen importlib._bootstrap_external>", line 783, in exec_module
  File "<frozen importlib._bootstrap>", line 219, in _call_with_frames_removed
  File "E:\PyProg\ProstoTools(Original version)\Cogs\events.py", line 17, in <module>
    from Tools.database import DB
  File "E:\PyProg\ProstoTools(Original version)\Tools\database.py", line 7, in <module>
    cursor.execute("""CREATE TABLE IF NOT EXISTS users(
NameError: name 'cursor' is not defined

The above exception was the direct cause of the following exception:

Traceback (most recent call last):
  File "bot.py", line 75, in <module>
    client.load_extension(f'Cogs.{filename[:-3]}')
  File "C:\Users\ProstoChelovek\AppData\Local\Programs\Python\Python38-32\lib\site-packages\discord\ext\commands\bot.py", line 653, in load_extension
    self._load_from_module_spec(spec, name)
  File "C:\Users\ProstoChelovek\AppData\Local\Programs\Python\Python38-32\lib\site-packages\discord\ext\commands\bot.py", line 599, in _load_from_module_spec
    raise errors.ExtensionFailed(key, e) from e
discord.ext.commands.errors.ExtensionFailed: Extension 'Cogs.events' raised an error: NameError: name 'cursor' is not defined

=============================================================

=============================================================
Время: 2020-07-21 13:56:38.748458

Ошибка:
Traceback (most recent call last):
  File "C:\Users\ProstoChelovek\AppData\Local\Programs\Python\Python38-32\lib\site-packages\discord\ext\commands\bot.py", line 596, in _load_from_module_spec
    spec.loader.exec_module(lib)
  File "<frozen importlib._bootstrap_external>", line 783, in exec_module
  File "<frozen importlib._bootstrap>", line 219, in _call_with_frames_removed
  File "E:\PyProg\ProstoTools(Original version)\Cogs\different.py", line 12, in <module>
    from Tools.database import DB
  File "E:\PyProg\ProstoTools(Original version)\Tools\database.py", line 7, in <module>
    cursor.execute("""CREATE TABLE IF NOT EXISTS users(
NameError: name 'cursor' is not defined

The above exception was the direct cause of the following exception:

Traceback (most recent call last):
  File "bot.py", line 75, in <module>
    client.load_extension(f'Cogs.{filename[:-3]}')
  File "C:\Users\ProstoChelovek\AppData\Local\Programs\Python\Python38-32\lib\site-packages\discord\ext\commands\bot.py", line 653, in load_extension
    self._load_from_module_spec(spec, name)
  File "C:\Users\ProstoChelovek\AppData\Local\Programs\Python\Python38-32\lib\site-packages\discord\ext\commands\bot.py", line 599, in _load_from_module_spec
    raise errors.ExtensionFailed(key, e) from e
discord.ext.commands.errors.ExtensionFailed: Extension 'Cogs.different' raised an error: NameError: name 'cursor' is not defined

=============================================================

=============================================================
Время: 2020-07-21 13:56:41.632749

Ошибка:
Traceback (most recent call last):
  File "C:\Users\ProstoChelovek\AppData\Local\Programs\Python\Python38-32\lib\site-packages\discord\ext\commands\bot.py", line 596, in _load_from_module_spec
    spec.loader.exec_module(lib)
  File "<frozen importlib._bootstrap_external>", line 783, in exec_module
  File "<frozen importlib._bootstrap>", line 219, in _call_with_frames_removed
  File "E:\PyProg\ProstoTools(Original version)\Cogs\events.py", line 17, in <module>
    from Tools.database import DB
  File "E:\PyProg\ProstoTools(Original version)\Tools\database.py", line 7, in <module>
    cursor.execute("""CREATE TABLE IF NOT EXISTS users(
NameError: name 'cursor' is not defined

The above exception was the direct cause of the following exception:

Traceback (most recent call last):
  File "bot.py", line 75, in <module>
    client.load_extension(f'Cogs.{filename[:-3]}')
  File "C:\Users\ProstoChelovek\AppData\Local\Programs\Python\Python38-32\lib\site-packages\discord\ext\commands\bot.py", line 653, in load_extension
    self._load_from_module_spec(spec, name)
  File "C:\Users\ProstoChelovek\AppData\Local\Programs\Python\Python38-32\lib\site-packages\discord\ext\commands\bot.py", line 599, in _load_from_module_spec
    raise errors.ExtensionFailed(key, e) from e
discord.ext.commands.errors.ExtensionFailed: Extension 'Cogs.events' raised an error: NameError: name 'cursor' is not defined

=============================================================

=============================================================
Время: 2020-07-21 13:58:00.248178

Ошибка:
Traceback (most recent call last):
  File "C:\Users\ProstoChelovek\AppData\Local\Programs\Python\Python38-32\lib\site-packages\discord\ext\commands\bot.py", line 596, in _load_from_module_spec
    spec.loader.exec_module(lib)
  File "<frozen importlib._bootstrap_external>", line 783, in exec_module
  File "<frozen importlib._bootstrap>", line 219, in _call_with_frames_removed
  File "E:\PyProg\ProstoTools(Original version)\Cogs\different.py", line 12, in <module>
    from Tools.database import DB
  File "E:\PyProg\ProstoTools(Original version)\Tools\database.py", line 7, in <module>
    cursor.execute("""CREATE TABLE IF NOT EXISTS users(
NameError: name 'cursor' is not defined

The above exception was the direct cause of the following exception:

Traceback (most recent call last):
  File "bot.py", line 75, in <module>
    client.load_extension(f'Cogs.{filename[:-3]}')
  File "C:\Users\ProstoChelovek\AppData\Local\Programs\Python\Python38-32\lib\site-packages\discord\ext\commands\bot.py", line 653, in load_extension
    self._load_from_module_spec(spec, name)
  File "C:\Users\ProstoChelovek\AppData\Local\Programs\Python\Python38-32\lib\site-packages\discord\ext\commands\bot.py", line 599, in _load_from_module_spec
    raise errors.ExtensionFailed(key, e) from e
discord.ext.commands.errors.ExtensionFailed: Extension 'Cogs.different' raised an error: NameError: name 'cursor' is not defined

=============================================================

=============================================================
Время: 2020-07-21 13:58:00.481554

Ошибка:
Traceback (most recent call last):
  File "C:\Users\ProstoChelovek\AppData\Local\Programs\Python\Python38-32\lib\site-packages\discord\ext\commands\bot.py", line 596, in _load_from_module_spec
    spec.loader.exec_module(lib)
  File "<frozen importlib._bootstrap_external>", line 783, in exec_module
  File "<frozen importlib._bootstrap>", line 219, in _call_with_frames_removed
  File "E:\PyProg\ProstoTools(Original version)\Cogs\events.py", line 17, in <module>
    from Tools.database import DB
  File "E:\PyProg\ProstoTools(Original version)\Tools\database.py", line 7, in <module>
    cursor.execute("""CREATE TABLE IF NOT EXISTS users(
NameError: name 'cursor' is not defined

The above exception was the direct cause of the following exception:

Traceback (most recent call last):
  File "bot.py", line 75, in <module>
    client.load_extension(f'Cogs.{filename[:-3]}')
  File "C:\Users\ProstoChelovek\AppData\Local\Programs\Python\Python38-32\lib\site-packages\discord\ext\commands\bot.py", line 653, in load_extension
    self._load_from_module_spec(spec, name)
  File "C:\Users\ProstoChelovek\AppData\Local\Programs\Python\Python38-32\lib\site-packages\discord\ext\commands\bot.py", line 599, in _load_from_module_spec
    raise errors.ExtensionFailed(key, e) from e
discord.ext.commands.errors.ExtensionFailed: Extension 'Cogs.events' raised an error: NameError: name 'cursor' is not defined

=============================================================

=============================================================
Время: 2020-07-21 13:56:38.748458

Ошибка:
Traceback (most recent call last):
  File "C:\Users\ProstoChelovek\AppData\Local\Programs\Python\Python38-32\lib\site-packages\discord\ext\commands\bot.py", line 596, in _load_from_module_spec
    spec.loader.exec_module(lib)
  File "<frozen importlib._bootstrap_external>", line 783, in exec_module
  File "<frozen importlib._bootstrap>", line 219, in _call_with_frames_removed
  File "E:\PyProg\ProstoTools(Original version)\Cogs\different.py", line 12, in <module>
    from Tools.database import DB
  File "E:\PyProg\ProstoTools(Original version)\Tools\database.py", line 7, in <module>
    cursor.execute("""CREATE TABLE IF NOT EXISTS users(
NameError: name 'cursor' is not defined

The above exception was the direct cause of the following exception:

Traceback (most recent call last):
  File "bot.py", line 75, in <module>
    client.load_extension(f'Cogs.{filename[:-3]}')
  File "C:\Users\ProstoChelovek\AppData\Local\Programs\Python\Python38-32\lib\site-packages\discord\ext\commands\bot.py", line 653, in load_extension
    self._load_from_module_spec(spec, name)
  File "C:\Users\ProstoChelovek\AppData\Local\Programs\Python\Python38-32\lib\site-packages\discord\ext\commands\bot.py", line 599, in _load_from_module_spec
    raise errors.ExtensionFailed(key, e) from e
discord.ext.commands.errors.ExtensionFailed: Extension 'Cogs.different' raised an error: NameError: name 'cursor' is not defined

=============================================================

=============================================================
Время: 2020-07-21 13:56:41.632749

Ошибка:
Traceback (most recent call last):
  File "C:\Users\ProstoChelovek\AppData\Local\Programs\Python\Python38-32\lib\site-packages\discord\ext\commands\bot.py", line 596, in _load_from_module_spec
    spec.loader.exec_module(lib)
  File "<frozen importlib._bootstrap_external>", line 783, in exec_module
  File "<frozen importlib._bootstrap>", line 219, in _call_with_frames_removed
  File "E:\PyProg\ProstoTools(Original version)\Cogs\events.py", line 17, in <module>
    from Tools.database import DB
  File "E:\PyProg\ProstoTools(Original version)\Tools\database.py", line 7, in <module>
    cursor.execute("""CREATE TABLE IF NOT EXISTS users(
NameError: name 'cursor' is not defined

The above exception was the direct cause of the following exception:

Traceback (most recent call last):
  File "bot.py", line 75, in <module>
    client.load_extension(f'Cogs.{filename[:-3]}')
  File "C:\Users\ProstoChelovek\AppData\Local\Programs\Python\Python38-32\lib\site-packages\discord\ext\commands\bot.py", line 653, in load_extension
    self._load_from_module_spec(spec, name)
  File "C:\Users\ProstoChelovek\AppData\Local\Programs\Python\Python38-32\lib\site-packages\discord\ext\commands\bot.py", line 599, in _load_from_module_spec
    raise errors.ExtensionFailed(key, e) from e
discord.ext.commands.errors.ExtensionFailed: Extension 'Cogs.events' raised an error: NameError: name 'cursor' is not defined

=============================================================

=============================================================
Время: 2020-07-21 13:56:38.748458

Ошибка:
Traceback (most recent call last):
  File "C:\Users\ProstoChelovek\AppData\Local\Programs\Python\Python38-32\lib\site-packages\discord\ext\commands\bot.py", line 596, in _load_from_module_spec
    spec.loader.exec_module(lib)
  File "<frozen importlib._bootstrap_external>", line 783, in exec_module
  File "<frozen importlib._bootstrap>", line 219, in _call_with_frames_removed
  File "E:\PyProg\ProstoTools(Original version)\Cogs\different.py", line 12, in <module>
    from Tools.database import DB
  File "E:\PyProg\ProstoTools(Original version)\Tools\database.py", line 7, in <module>
    cursor.execute("""CREATE TABLE IF NOT EXISTS users(
NameError: name 'cursor' is not defined

The above exception was the direct cause of the following exception:

Traceback (most recent call last):
  File "bot.py", line 75, in <module>
    client.load_extension(f'Cogs.{filename[:-3]}')
  File "C:\Users\ProstoChelovek\AppData\Local\Programs\Python\Python38-32\lib\site-packages\discord\ext\commands\bot.py", line 653, in load_extension
    self._load_from_module_spec(spec, name)
  File "C:\Users\ProstoChelovek\AppData\Local\Programs\Python\Python38-32\lib\site-packages\discord\ext\commands\bot.py", line 599, in _load_from_module_spec
    raise errors.ExtensionFailed(key, e) from e
discord.ext.commands.errors.ExtensionFailed: Extension 'Cogs.different' raised an error: NameError: name 'cursor' is not defined

=============================================================

=============================================================
Время: 2020-07-21 13:56:41.632749

Ошибка:
Traceback (most recent call last):
  File "C:\Users\ProstoChelovek\AppData\Local\Programs\Python\Python38-32\lib\site-packages\discord\ext\commands\bot.py", line 596, in _load_from_module_spec
    spec.loader.exec_module(lib)
  File "<frozen importlib._bootstrap_external>", line 783, in exec_module
  File "<frozen importlib._bootstrap>", line 219, in _call_with_frames_removed
  File "E:\PyProg\ProstoTools(Original version)\Cogs\events.py", line 17, in <module>
    from Tools.database import DB
  File "E:\PyProg\ProstoTools(Original version)\Tools\database.py", line 7, in <module>
    cursor.execute("""CREATE TABLE IF NOT EXISTS users(
NameError: name 'cursor' is not defined

The above exception was the direct cause of the following exception:

Traceback (most recent call last):
  File "bot.py", line 75, in <module>
    client.load_extension(f'Cogs.{filename[:-3]}')
  File "C:\Users\ProstoChelovek\AppData\Local\Programs\Python\Python38-32\lib\site-packages\discord\ext\commands\bot.py", line 653, in load_extension
    self._load_from_module_spec(spec, name)
  File "C:\Users\ProstoChelovek\AppData\Local\Programs\Python\Python38-32\lib\site-packages\discord\ext\commands\bot.py", line 599, in _load_from_module_spec
    raise errors.ExtensionFailed(key, e) from e
discord.ext.commands.errors.ExtensionFailed: Extension 'Cogs.events' raised an error: NameError: name 'cursor' is not defined

=============================================================

=============================================================
Время: 2020-07-21 13:58:00.248178

Ошибка:
Traceback (most recent call last):
  File "C:\Users\ProstoChelovek\AppData\Local\Programs\Python\Python38-32\lib\site-packages\discord\ext\commands\bot.py", line 596, in _load_from_module_spec
    spec.loader.exec_module(lib)
  File "<frozen importlib._bootstrap_external>", line 783, in exec_module
  File "<frozen importlib._bootstrap>", line 219, in _call_with_frames_removed
  File "E:\PyProg\ProstoTools(Original version)\Cogs\different.py", line 12, in <module>
    from Tools.database import DB
  File "E:\PyProg\ProstoTools(Original version)\Tools\database.py", line 7, in <module>
    cursor.execute("""CREATE TABLE IF NOT EXISTS users(
NameError: name 'cursor' is not defined

The above exception was the direct cause of the following exception:

Traceback (most recent call last):
  File "bot.py", line 75, in <module>
    client.load_extension(f'Cogs.{filename[:-3]}')
  File "C:\Users\ProstoChelovek\AppData\Local\Programs\Python\Python38-32\lib\site-packages\discord\ext\commands\bot.py", line 653, in load_extension
    self._load_from_module_spec(spec, name)
  File "C:\Users\ProstoChelovek\AppData\Local\Programs\Python\Python38-32\lib\site-packages\discord\ext\commands\bot.py", line 599, in _load_from_module_spec
    raise errors.ExtensionFailed(key, e) from e
discord.ext.commands.errors.ExtensionFailed: Extension 'Cogs.different' raised an error: NameError: name 'cursor' is not defined

=============================================================

=============================================================
Время: 2020-07-21 13:58:00.481554

Ошибка:
Traceback (most recent call last):
  File "C:\Users\ProstoChelovek\AppData\Local\Programs\Python\Python38-32\lib\site-packages\discord\ext\commands\bot.py", line 596, in _load_from_module_spec
    spec.loader.exec_module(lib)
  File "<frozen importlib._bootstrap_external>", line 783, in exec_module
  File "<frozen importlib._bootstrap>", line 219, in _call_with_frames_removed
  File "E:\PyProg\ProstoTools(Original version)\Cogs\events.py", line 17, in <module>
    from Tools.database import DB
  File "E:\PyProg\ProstoTools(Original version)\Tools\database.py", line 7, in <module>
    cursor.execute("""CREATE TABLE IF NOT EXISTS users(
NameError: name 'cursor' is not defined

The above exception was the direct cause of the following exception:

Traceback (most recent call last):
  File "bot.py", line 75, in <module>
    client.load_extension(f'Cogs.{filename[:-3]}')
  File "C:\Users\ProstoChelovek\AppData\Local\Programs\Python\Python38-32\lib\site-packages\discord\ext\commands\bot.py", line 653, in load_extension
    self._load_from_module_spec(spec, name)
  File "C:\Users\ProstoChelovek\AppData\Local\Programs\Python\Python38-32\lib\site-packages\discord\ext\commands\bot.py", line 599, in _load_from_module_spec
    raise errors.ExtensionFailed(key, e) from e
discord.ext.commands.errors.ExtensionFailed: Extension 'Cogs.events' raised an error: NameError: name 'cursor' is not defined

=============================================================

=============================================================
Время: 2020-07-21 14:06:45.407501

Ошибка:
Traceback (most recent call last):
  File "C:\Users\ProstoChelovek\AppData\Local\Programs\Python\Python38-32\lib\site-packages\discord\ext\commands\bot.py", line 596, in _load_from_module_spec
    spec.loader.exec_module(lib)
  File "<frozen importlib._bootstrap_external>", line 783, in exec_module
  File "<frozen importlib._bootstrap>", line 219, in _call_with_frames_removed
  File "E:\PyProg\ProstoTools(Original version)\Cogs\different.py", line 12, in <module>
    from Tools.database import DB
  File "E:\PyProg\ProstoTools(Original version)\Tools\database.py", line 40, in <module>
    class DB:
  File "E:\PyProg\ProstoTools(Original version)\Tools\database.py", line 46, in DB
    conn = mysql.connector.connect(user = 'root', password = '9fr8-PkM;M4+', host = 'localhost', database = self.database)
NameError: name 'self' is not defined

The above exception was the direct cause of the following exception:

Traceback (most recent call last):
  File "bot.py", line 75, in <module>
    client.load_extension(f'Cogs.{filename[:-3]}')
  File "C:\Users\ProstoChelovek\AppData\Local\Programs\Python\Python38-32\lib\site-packages\discord\ext\commands\bot.py", line 653, in load_extension
    self._load_from_module_spec(spec, name)
  File "C:\Users\ProstoChelovek\AppData\Local\Programs\Python\Python38-32\lib\site-packages\discord\ext\commands\bot.py", line 599, in _load_from_module_spec
    raise errors.ExtensionFailed(key, e) from e
discord.ext.commands.errors.ExtensionFailed: Extension 'Cogs.different' raised an error: NameError: name 'self' is not defined

=============================================================

=============================================================
Время: 2020-07-21 14:06:45.658829

Ошибка:
Traceback (most recent call last):
  File "C:\Users\ProstoChelovek\AppData\Local\Programs\Python\Python38-32\lib\site-packages\discord\ext\commands\bot.py", line 596, in _load_from_module_spec
    spec.loader.exec_module(lib)
  File "<frozen importlib._bootstrap_external>", line 783, in exec_module
  File "<frozen importlib._bootstrap>", line 219, in _call_with_frames_removed
  File "E:\PyProg\ProstoTools(Original version)\Cogs\events.py", line 17, in <module>
    from Tools.database import DB
  File "E:\PyProg\ProstoTools(Original version)\Tools\database.py", line 40, in <module>
    class DB:
  File "E:\PyProg\ProstoTools(Original version)\Tools\database.py", line 46, in DB
    conn = mysql.connector.connect(user = 'root', password = '9fr8-PkM;M4+', host = 'localhost', database = self.database)
NameError: name 'self' is not defined

The above exception was the direct cause of the following exception:

Traceback (most recent call last):
  File "bot.py", line 75, in <module>
    client.load_extension(f'Cogs.{filename[:-3]}')
  File "C:\Users\ProstoChelovek\AppData\Local\Programs\Python\Python38-32\lib\site-packages\discord\ext\commands\bot.py", line 653, in load_extension
    self._load_from_module_spec(spec, name)
  File "C:\Users\ProstoChelovek\AppData\Local\Programs\Python\Python38-32\lib\site-packages\discord\ext\commands\bot.py", line 599, in _load_from_module_spec
    raise errors.ExtensionFailed(key, e) from e
discord.ext.commands.errors.ExtensionFailed: Extension 'Cogs.events' raised an error: NameError: name 'self' is not defined

=============================================================

=============================================================
Время: 2020-07-21 13:56:38.748458

Ошибка:
Traceback (most recent call last):
  File "C:\Users\ProstoChelovek\AppData\Local\Programs\Python\Python38-32\lib\site-packages\discord\ext\commands\bot.py", line 596, in _load_from_module_spec
    spec.loader.exec_module(lib)
  File "<frozen importlib._bootstrap_external>", line 783, in exec_module
  File "<frozen importlib._bootstrap>", line 219, in _call_with_frames_removed
  File "E:\PyProg\ProstoTools(Original version)\Cogs\different.py", line 12, in <module>
    from Tools.database import DB
  File "E:\PyProg\ProstoTools(Original version)\Tools\database.py", line 7, in <module>
    cursor.execute("""CREATE TABLE IF NOT EXISTS users(
NameError: name 'cursor' is not defined

The above exception was the direct cause of the following exception:

Traceback (most recent call last):
  File "bot.py", line 75, in <module>
    client.load_extension(f'Cogs.{filename[:-3]}')
  File "C:\Users\ProstoChelovek\AppData\Local\Programs\Python\Python38-32\lib\site-packages\discord\ext\commands\bot.py", line 653, in load_extension
    self._load_from_module_spec(spec, name)
  File "C:\Users\ProstoChelovek\AppData\Local\Programs\Python\Python38-32\lib\site-packages\discord\ext\commands\bot.py", line 599, in _load_from_module_spec
    raise errors.ExtensionFailed(key, e) from e
discord.ext.commands.errors.ExtensionFailed: Extension 'Cogs.different' raised an error: NameError: name 'cursor' is not defined

=============================================================

=============================================================
Время: 2020-07-21 13:56:41.632749

Ошибка:
Traceback (most recent call last):
  File "C:\Users\ProstoChelovek\AppData\Local\Programs\Python\Python38-32\lib\site-packages\discord\ext\commands\bot.py", line 596, in _load_from_module_spec
    spec.loader.exec_module(lib)
  File "<frozen importlib._bootstrap_external>", line 783, in exec_module
  File "<frozen importlib._bootstrap>", line 219, in _call_with_frames_removed
  File "E:\PyProg\ProstoTools(Original version)\Cogs\events.py", line 17, in <module>
    from Tools.database import DB
  File "E:\PyProg\ProstoTools(Original version)\Tools\database.py", line 7, in <module>
    cursor.execute("""CREATE TABLE IF NOT EXISTS users(
NameError: name 'cursor' is not defined

The above exception was the direct cause of the following exception:

Traceback (most recent call last):
  File "bot.py", line 75, in <module>
    client.load_extension(f'Cogs.{filename[:-3]}')
  File "C:\Users\ProstoChelovek\AppData\Local\Programs\Python\Python38-32\lib\site-packages\discord\ext\commands\bot.py", line 653, in load_extension
    self._load_from_module_spec(spec, name)
  File "C:\Users\ProstoChelovek\AppData\Local\Programs\Python\Python38-32\lib\site-packages\discord\ext\commands\bot.py", line 599, in _load_from_module_spec
    raise errors.ExtensionFailed(key, e) from e
discord.ext.commands.errors.ExtensionFailed: Extension 'Cogs.events' raised an error: NameError: name 'cursor' is not defined

=============================================================

=============================================================
Время: 2020-07-21 13:56:38.748458

Ошибка:
Traceback (most recent call last):
  File "C:\Users\ProstoChelovek\AppData\Local\Programs\Python\Python38-32\lib\site-packages\discord\ext\commands\bot.py", line 596, in _load_from_module_spec
    spec.loader.exec_module(lib)
  File "<frozen importlib._bootstrap_external>", line 783, in exec_module
  File "<frozen importlib._bootstrap>", line 219, in _call_with_frames_removed
  File "E:\PyProg\ProstoTools(Original version)\Cogs\different.py", line 12, in <module>
    from Tools.database import DB
  File "E:\PyProg\ProstoTools(Original version)\Tools\database.py", line 7, in <module>
    cursor.execute("""CREATE TABLE IF NOT EXISTS users(
NameError: name 'cursor' is not defined

The above exception was the direct cause of the following exception:

Traceback (most recent call last):
  File "bot.py", line 75, in <module>
    client.load_extension(f'Cogs.{filename[:-3]}')
  File "C:\Users\ProstoChelovek\AppData\Local\Programs\Python\Python38-32\lib\site-packages\discord\ext\commands\bot.py", line 653, in load_extension
    self._load_from_module_spec(spec, name)
  File "C:\Users\ProstoChelovek\AppData\Local\Programs\Python\Python38-32\lib\site-packages\discord\ext\commands\bot.py", line 599, in _load_from_module_spec
    raise errors.ExtensionFailed(key, e) from e
discord.ext.commands.errors.ExtensionFailed: Extension 'Cogs.different' raised an error: NameError: name 'cursor' is not defined

=============================================================

=============================================================
Время: 2020-07-21 13:56:41.632749

Ошибка:
Traceback (most recent call last):
  File "C:\Users\ProstoChelovek\AppData\Local\Programs\Python\Python38-32\lib\site-packages\discord\ext\commands\bot.py", line 596, in _load_from_module_spec
    spec.loader.exec_module(lib)
  File "<frozen importlib._bootstrap_external>", line 783, in exec_module
  File "<frozen importlib._bootstrap>", line 219, in _call_with_frames_removed
  File "E:\PyProg\ProstoTools(Original version)\Cogs\events.py", line 17, in <module>
    from Tools.database import DB
  File "E:\PyProg\ProstoTools(Original version)\Tools\database.py", line 7, in <module>
    cursor.execute("""CREATE TABLE IF NOT EXISTS users(
NameError: name 'cursor' is not defined

The above exception was the direct cause of the following exception:

Traceback (most recent call last):
  File "bot.py", line 75, in <module>
    client.load_extension(f'Cogs.{filename[:-3]}')
  File "C:\Users\ProstoChelovek\AppData\Local\Programs\Python\Python38-32\lib\site-packages\discord\ext\commands\bot.py", line 653, in load_extension
    self._load_from_module_spec(spec, name)
  File "C:\Users\ProstoChelovek\AppData\Local\Programs\Python\Python38-32\lib\site-packages\discord\ext\commands\bot.py", line 599, in _load_from_module_spec
    raise errors.ExtensionFailed(key, e) from e
discord.ext.commands.errors.ExtensionFailed: Extension 'Cogs.events' raised an error: NameError: name 'cursor' is not defined

=============================================================

=============================================================
Время: 2020-07-21 13:58:00.248178

Ошибка:
Traceback (most recent call last):
  File "C:\Users\ProstoChelovek\AppData\Local\Programs\Python\Python38-32\lib\site-packages\discord\ext\commands\bot.py", line 596, in _load_from_module_spec
    spec.loader.exec_module(lib)
  File "<frozen importlib._bootstrap_external>", line 783, in exec_module
  File "<frozen importlib._bootstrap>", line 219, in _call_with_frames_removed
  File "E:\PyProg\ProstoTools(Original version)\Cogs\different.py", line 12, in <module>
    from Tools.database import DB
  File "E:\PyProg\ProstoTools(Original version)\Tools\database.py", line 7, in <module>
    cursor.execute("""CREATE TABLE IF NOT EXISTS users(
NameError: name 'cursor' is not defined

The above exception was the direct cause of the following exception:

Traceback (most recent call last):
  File "bot.py", line 75, in <module>
    client.load_extension(f'Cogs.{filename[:-3]}')
  File "C:\Users\ProstoChelovek\AppData\Local\Programs\Python\Python38-32\lib\site-packages\discord\ext\commands\bot.py", line 653, in load_extension
    self._load_from_module_spec(spec, name)
  File "C:\Users\ProstoChelovek\AppData\Local\Programs\Python\Python38-32\lib\site-packages\discord\ext\commands\bot.py", line 599, in _load_from_module_spec
    raise errors.ExtensionFailed(key, e) from e
discord.ext.commands.errors.ExtensionFailed: Extension 'Cogs.different' raised an error: NameError: name 'cursor' is not defined

=============================================================

=============================================================
Время: 2020-07-21 13:58:00.481554

Ошибка:
Traceback (most recent call last):
  File "C:\Users\ProstoChelovek\AppData\Local\Programs\Python\Python38-32\lib\site-packages\discord\ext\commands\bot.py", line 596, in _load_from_module_spec
    spec.loader.exec_module(lib)
  File "<frozen importlib._bootstrap_external>", line 783, in exec_module
  File "<frozen importlib._bootstrap>", line 219, in _call_with_frames_removed
  File "E:\PyProg\ProstoTools(Original version)\Cogs\events.py", line 17, in <module>
    from Tools.database import DB
  File "E:\PyProg\ProstoTools(Original version)\Tools\database.py", line 7, in <module>
    cursor.execute("""CREATE TABLE IF NOT EXISTS users(
NameError: name 'cursor' is not defined

The above exception was the direct cause of the following exception:

Traceback (most recent call last):
  File "bot.py", line 75, in <module>
    client.load_extension(f'Cogs.{filename[:-3]}')
  File "C:\Users\ProstoChelovek\AppData\Local\Programs\Python\Python38-32\lib\site-packages\discord\ext\commands\bot.py", line 653, in load_extension
    self._load_from_module_spec(spec, name)
  File "C:\Users\ProstoChelovek\AppData\Local\Programs\Python\Python38-32\lib\site-packages\discord\ext\commands\bot.py", line 599, in _load_from_module_spec
    raise errors.ExtensionFailed(key, e) from e
discord.ext.commands.errors.ExtensionFailed: Extension 'Cogs.events' raised an error: NameError: name 'cursor' is not defined

=============================================================

=============================================================
Время: 2020-07-21 13:56:38.748458

Ошибка:
Traceback (most recent call last):
  File "C:\Users\ProstoChelovek\AppData\Local\Programs\Python\Python38-32\lib\site-packages\discord\ext\commands\bot.py", line 596, in _load_from_module_spec
    spec.loader.exec_module(lib)
  File "<frozen importlib._bootstrap_external>", line 783, in exec_module
  File "<frozen importlib._bootstrap>", line 219, in _call_with_frames_removed
  File "E:\PyProg\ProstoTools(Original version)\Cogs\different.py", line 12, in <module>
    from Tools.database import DB
  File "E:\PyProg\ProstoTools(Original version)\Tools\database.py", line 7, in <module>
    cursor.execute("""CREATE TABLE IF NOT EXISTS users(
NameError: name 'cursor' is not defined

The above exception was the direct cause of the following exception:

Traceback (most recent call last):
  File "bot.py", line 75, in <module>
    client.load_extension(f'Cogs.{filename[:-3]}')
  File "C:\Users\ProstoChelovek\AppData\Local\Programs\Python\Python38-32\lib\site-packages\discord\ext\commands\bot.py", line 653, in load_extension
    self._load_from_module_spec(spec, name)
  File "C:\Users\ProstoChelovek\AppData\Local\Programs\Python\Python38-32\lib\site-packages\discord\ext\commands\bot.py", line 599, in _load_from_module_spec
    raise errors.ExtensionFailed(key, e) from e
discord.ext.commands.errors.ExtensionFailed: Extension 'Cogs.different' raised an error: NameError: name 'cursor' is not defined

=============================================================

=============================================================
Время: 2020-07-21 13:56:41.632749

Ошибка:
Traceback (most recent call last):
  File "C:\Users\ProstoChelovek\AppData\Local\Programs\Python\Python38-32\lib\site-packages\discord\ext\commands\bot.py", line 596, in _load_from_module_spec
    spec.loader.exec_module(lib)
  File "<frozen importlib._bootstrap_external>", line 783, in exec_module
  File "<frozen importlib._bootstrap>", line 219, in _call_with_frames_removed
  File "E:\PyProg\ProstoTools(Original version)\Cogs\events.py", line 17, in <module>
    from Tools.database import DB
  File "E:\PyProg\ProstoTools(Original version)\Tools\database.py", line 7, in <module>
    cursor.execute("""CREATE TABLE IF NOT EXISTS users(
NameError: name 'cursor' is not defined

The above exception was the direct cause of the following exception:

Traceback (most recent call last):
  File "bot.py", line 75, in <module>
    client.load_extension(f'Cogs.{filename[:-3]}')
  File "C:\Users\ProstoChelovek\AppData\Local\Programs\Python\Python38-32\lib\site-packages\discord\ext\commands\bot.py", line 653, in load_extension
    self._load_from_module_spec(spec, name)
  File "C:\Users\ProstoChelovek\AppData\Local\Programs\Python\Python38-32\lib\site-packages\discord\ext\commands\bot.py", line 599, in _load_from_module_spec
    raise errors.ExtensionFailed(key, e) from e
discord.ext.commands.errors.ExtensionFailed: Extension 'Cogs.events' raised an error: NameError: name 'cursor' is not defined

=============================================================

=============================================================
Время: 2020-07-21 13:56:38.748458

Ошибка:
Traceback (most recent call last):
  File "C:\Users\ProstoChelovek\AppData\Local\Programs\Python\Python38-32\lib\site-packages\discord\ext\commands\bot.py", line 596, in _load_from_module_spec
    spec.loader.exec_module(lib)
  File "<frozen importlib._bootstrap_external>", line 783, in exec_module
  File "<frozen importlib._bootstrap>", line 219, in _call_with_frames_removed
  File "E:\PyProg\ProstoTools(Original version)\Cogs\different.py", line 12, in <module>
    from Tools.database import DB
  File "E:\PyProg\ProstoTools(Original version)\Tools\database.py", line 7, in <module>
    cursor.execute("""CREATE TABLE IF NOT EXISTS users(
NameError: name 'cursor' is not defined

The above exception was the direct cause of the following exception:

Traceback (most recent call last):
  File "bot.py", line 75, in <module>
    client.load_extension(f'Cogs.{filename[:-3]}')
  File "C:\Users\ProstoChelovek\AppData\Local\Programs\Python\Python38-32\lib\site-packages\discord\ext\commands\bot.py", line 653, in load_extension
    self._load_from_module_spec(spec, name)
  File "C:\Users\ProstoChelovek\AppData\Local\Programs\Python\Python38-32\lib\site-packages\discord\ext\commands\bot.py", line 599, in _load_from_module_spec
    raise errors.ExtensionFailed(key, e) from e
discord.ext.commands.errors.ExtensionFailed: Extension 'Cogs.different' raised an error: NameError: name 'cursor' is not defined

=============================================================

=============================================================
Время: 2020-07-21 13:56:41.632749

Ошибка:
Traceback (most recent call last):
  File "C:\Users\ProstoChelovek\AppData\Local\Programs\Python\Python38-32\lib\site-packages\discord\ext\commands\bot.py", line 596, in _load_from_module_spec
    spec.loader.exec_module(lib)
  File "<frozen importlib._bootstrap_external>", line 783, in exec_module
  File "<frozen importlib._bootstrap>", line 219, in _call_with_frames_removed
  File "E:\PyProg\ProstoTools(Original version)\Cogs\events.py", line 17, in <module>
    from Tools.database import DB
  File "E:\PyProg\ProstoTools(Original version)\Tools\database.py", line 7, in <module>
    cursor.execute("""CREATE TABLE IF NOT EXISTS users(
NameError: name 'cursor' is not defined

The above exception was the direct cause of the following exception:

Traceback (most recent call last):
  File "bot.py", line 75, in <module>
    client.load_extension(f'Cogs.{filename[:-3]}')
  File "C:\Users\ProstoChelovek\AppData\Local\Programs\Python\Python38-32\lib\site-packages\discord\ext\commands\bot.py", line 653, in load_extension
    self._load_from_module_spec(spec, name)
  File "C:\Users\ProstoChelovek\AppData\Local\Programs\Python\Python38-32\lib\site-packages\discord\ext\commands\bot.py", line 599, in _load_from_module_spec
    raise errors.ExtensionFailed(key, e) from e
discord.ext.commands.errors.ExtensionFailed: Extension 'Cogs.events' raised an error: NameError: name 'cursor' is not defined

=============================================================

=============================================================
Время: 2020-07-21 13:58:00.248178

Ошибка:
Traceback (most recent call last):
  File "C:\Users\ProstoChelovek\AppData\Local\Programs\Python\Python38-32\lib\site-packages\discord\ext\commands\bot.py", line 596, in _load_from_module_spec
    spec.loader.exec_module(lib)
  File "<frozen importlib._bootstrap_external>", line 783, in exec_module
  File "<frozen importlib._bootstrap>", line 219, in _call_with_frames_removed
  File "E:\PyProg\ProstoTools(Original version)\Cogs\different.py", line 12, in <module>
    from Tools.database import DB
  File "E:\PyProg\ProstoTools(Original version)\Tools\database.py", line 7, in <module>
    cursor.execute("""CREATE TABLE IF NOT EXISTS users(
NameError: name 'cursor' is not defined

The above exception was the direct cause of the following exception:

Traceback (most recent call last):
  File "bot.py", line 75, in <module>
    client.load_extension(f'Cogs.{filename[:-3]}')
  File "C:\Users\ProstoChelovek\AppData\Local\Programs\Python\Python38-32\lib\site-packages\discord\ext\commands\bot.py", line 653, in load_extension
    self._load_from_module_spec(spec, name)
  File "C:\Users\ProstoChelovek\AppData\Local\Programs\Python\Python38-32\lib\site-packages\discord\ext\commands\bot.py", line 599, in _load_from_module_spec
    raise errors.ExtensionFailed(key, e) from e
discord.ext.commands.errors.ExtensionFailed: Extension 'Cogs.different' raised an error: NameError: name 'cursor' is not defined

=============================================================

=============================================================
Время: 2020-07-21 13:58:00.481554

Ошибка:
Traceback (most recent call last):
  File "C:\Users\ProstoChelovek\AppData\Local\Programs\Python\Python38-32\lib\site-packages\discord\ext\commands\bot.py", line 596, in _load_from_module_spec
    spec.loader.exec_module(lib)
  File "<frozen importlib._bootstrap_external>", line 783, in exec_module
  File "<frozen importlib._bootstrap>", line 219, in _call_with_frames_removed
  File "E:\PyProg\ProstoTools(Original version)\Cogs\events.py", line 17, in <module>
    from Tools.database import DB
  File "E:\PyProg\ProstoTools(Original version)\Tools\database.py", line 7, in <module>
    cursor.execute("""CREATE TABLE IF NOT EXISTS users(
NameError: name 'cursor' is not defined

The above exception was the direct cause of the following exception:

Traceback (most recent call last):
  File "bot.py", line 75, in <module>
    client.load_extension(f'Cogs.{filename[:-3]}')
  File "C:\Users\ProstoChelovek\AppData\Local\Programs\Python\Python38-32\lib\site-packages\discord\ext\commands\bot.py", line 653, in load_extension
    self._load_from_module_spec(spec, name)
  File "C:\Users\ProstoChelovek\AppData\Local\Programs\Python\Python38-32\lib\site-packages\discord\ext\commands\bot.py", line 599, in _load_from_module_spec
    raise errors.ExtensionFailed(key, e) from e
discord.ext.commands.errors.ExtensionFailed: Extension 'Cogs.events' raised an error: NameError: name 'cursor' is not defined

=============================================================

=============================================================
Время: 2020-07-21 14:06:45.407501

Ошибка:
Traceback (most recent call last):
  File "C:\Users\ProstoChelovek\AppData\Local\Programs\Python\Python38-32\lib\site-packages\discord\ext\commands\bot.py", line 596, in _load_from_module_spec
    spec.loader.exec_module(lib)
  File "<frozen importlib._bootstrap_external>", line 783, in exec_module
  File "<frozen importlib._bootstrap>", line 219, in _call_with_frames_removed
  File "E:\PyProg\ProstoTools(Original version)\Cogs\different.py", line 12, in <module>
    from Tools.database import DB
  File "E:\PyProg\ProstoTools(Original version)\Tools\database.py", line 40, in <module>
    class DB:
  File "E:\PyProg\ProstoTools(Original version)\Tools\database.py", line 46, in DB
    conn = mysql.connector.connect(user = 'root', password = '9fr8-PkM;M4+', host = 'localhost', database = self.database)
NameError: name 'self' is not defined

The above exception was the direct cause of the following exception:

Traceback (most recent call last):
  File "bot.py", line 75, in <module>
    client.load_extension(f'Cogs.{filename[:-3]}')
  File "C:\Users\ProstoChelovek\AppData\Local\Programs\Python\Python38-32\lib\site-packages\discord\ext\commands\bot.py", line 653, in load_extension
    self._load_from_module_spec(spec, name)
  File "C:\Users\ProstoChelovek\AppData\Local\Programs\Python\Python38-32\lib\site-packages\discord\ext\commands\bot.py", line 599, in _load_from_module_spec
    raise errors.ExtensionFailed(key, e) from e
discord.ext.commands.errors.ExtensionFailed: Extension 'Cogs.different' raised an error: NameError: name 'self' is not defined

=============================================================

=============================================================
Время: 2020-07-21 14:06:45.658829

Ошибка:
Traceback (most recent call last):
  File "C:\Users\ProstoChelovek\AppData\Local\Programs\Python\Python38-32\lib\site-packages\discord\ext\commands\bot.py", line 596, in _load_from_module_spec
    spec.loader.exec_module(lib)
  File "<frozen importlib._bootstrap_external>", line 783, in exec_module
  File "<frozen importlib._bootstrap>", line 219, in _call_with_frames_removed
  File "E:\PyProg\ProstoTools(Original version)\Cogs\events.py", line 17, in <module>
    from Tools.database import DB
  File "E:\PyProg\ProstoTools(Original version)\Tools\database.py", line 40, in <module>
    class DB:
  File "E:\PyProg\ProstoTools(Original version)\Tools\database.py", line 46, in DB
    conn = mysql.connector.connect(user = 'root', password = '9fr8-PkM;M4+', host = 'localhost', database = self.database)
NameError: name 'self' is not defined

The above exception was the direct cause of the following exception:

Traceback (most recent call last):
  File "bot.py", line 75, in <module>
    client.load_extension(f'Cogs.{filename[:-3]}')
  File "C:\Users\ProstoChelovek\AppData\Local\Programs\Python\Python38-32\lib\site-packages\discord\ext\commands\bot.py", line 653, in load_extension
    self._load_from_module_spec(spec, name)
  File "C:\Users\ProstoChelovek\AppData\Local\Programs\Python\Python38-32\lib\site-packages\discord\ext\commands\bot.py", line 599, in _load_from_module_spec
    raise errors.ExtensionFailed(key, e) from e
discord.ext.commands.errors.ExtensionFailed: Extension 'Cogs.events' raised an error: NameError: name 'self' is not defined

=============================================================

=============================================================
Время: 2020-07-21 14:07:25.087451

Ошибка:
Traceback (most recent call last):
  File "C:\Users\ProstoChelovek\AppData\Local\Programs\Python\Python38-32\lib\site-packages\discord\ext\commands\bot.py", line 596, in _load_from_module_spec
    spec.loader.exec_module(lib)
  File "<frozen importlib._bootstrap_external>", line 783, in exec_module
  File "<frozen importlib._bootstrap>", line 219, in _call_with_frames_removed
  File "E:\PyProg\ProstoTools(Original version)\Cogs\different.py", line 12, in <module>
    from Tools.database import DB
  File "E:\PyProg\ProstoTools(Original version)\Tools\database.py", line 40, in <module>
    class DB:
  File "E:\PyProg\ProstoTools(Original version)\Tools\database.py", line 46, in DB
    conn = mysql.connector.connect(user = 'root', password = '9fr8-PkM;M4+', host = 'localhost', database = database)
NameError: name 'database' is not defined

The above exception was the direct cause of the following exception:

Traceback (most recent call last):
  File "bot.py", line 75, in <module>
    client.load_extension(f'Cogs.{filename[:-3]}')
  File "C:\Users\ProstoChelovek\AppData\Local\Programs\Python\Python38-32\lib\site-packages\discord\ext\commands\bot.py", line 653, in load_extension
    self._load_from_module_spec(spec, name)
  File "C:\Users\ProstoChelovek\AppData\Local\Programs\Python\Python38-32\lib\site-packages\discord\ext\commands\bot.py", line 599, in _load_from_module_spec
    raise errors.ExtensionFailed(key, e) from e
discord.ext.commands.errors.ExtensionFailed: Extension 'Cogs.different' raised an error: NameError: name 'database' is not defined

=============================================================

=============================================================
Время: 2020-07-21 14:07:25.318832

Ошибка:
Traceback (most recent call last):
  File "C:\Users\ProstoChelovek\AppData\Local\Programs\Python\Python38-32\lib\site-packages\discord\ext\commands\bot.py", line 596, in _load_from_module_spec
    spec.loader.exec_module(lib)
  File "<frozen importlib._bootstrap_external>", line 783, in exec_module
  File "<frozen importlib._bootstrap>", line 219, in _call_with_frames_removed
  File "E:\PyProg\ProstoTools(Original version)\Cogs\events.py", line 17, in <module>
    from Tools.database import DB
  File "E:\PyProg\ProstoTools(Original version)\Tools\database.py", line 40, in <module>
    class DB:
  File "E:\PyProg\ProstoTools(Original version)\Tools\database.py", line 46, in DB
    conn = mysql.connector.connect(user = 'root', password = '9fr8-PkM;M4+', host = 'localhost', database = database)
NameError: name 'database' is not defined

The above exception was the direct cause of the following exception:

Traceback (most recent call last):
  File "bot.py", line 75, in <module>
    client.load_extension(f'Cogs.{filename[:-3]}')
  File "C:\Users\ProstoChelovek\AppData\Local\Programs\Python\Python38-32\lib\site-packages\discord\ext\commands\bot.py", line 653, in load_extension
    self._load_from_module_spec(spec, name)
  File "C:\Users\ProstoChelovek\AppData\Local\Programs\Python\Python38-32\lib\site-packages\discord\ext\commands\bot.py", line 599, in _load_from_module_spec
    raise errors.ExtensionFailed(key, e) from e
discord.ext.commands.errors.ExtensionFailed: Extension 'Cogs.events' raised an error: NameError: name 'database' is not defined

=============================================================

=============================================================
Время: 2020-07-21 19:52:01.708652

Ошибка:
Command raised an exception: NameError: name 'filecontent' is not defined
=============================================================

=============================================================
Время: 2020-07-21 20:04:38.552879

Ошибка:
You are on cooldown. Try again in 7015.54s
=============================================================

=============================================================
Время: 2020-07-21 20:05:01.109978

Ошибка:
Command "res_cd" is not found
=============================================================

=============================================================
Время: 2020-07-21 20:05:23.683995

Ошибка:
You are on cooldown. Try again in 6970.32s
=============================================================

=============================================================
Время: 2020-07-21 20:05:44.764912

Ошибка:
You are on cooldown. Try again in 6949.22s
=============================================================