

=============================================================
Время: 2020-07-12 11:47:35.606710

Ошибка:
Traceback (most recent call last):
  File "C:\Users\ProstoChelovek\AppData\Local\Programs\Python\Python38-32\lib\site-packages\discord\ext\commands\bot.py", line 596, in _load_from_module_spec
    spec.loader.exec_module(lib)
  File "<frozen importlib._bootstrap_external>", line 783, in exec_module
  File "<frozen importlib._bootstrap>", line 219, in _call_with_frames_removed
  File "E:\PyProg\ProstoTools(Original version)\Cogs\events.py", line 7, in <module>
    import moderate
ModuleNotFoundError: No module named 'moderate'

The above exception was the direct cause of the following exception:

Traceback (most recent call last):
  File "bot.py", line 75, in <module>
    client.load_extension(f'Cogs.{filename[:-3]}')
  File "C:\Users\ProstoChelovek\AppData\Local\Programs\Python\Python38-32\lib\site-packages\discord\ext\commands\bot.py", line 653, in load_extension
    self._load_from_module_spec(spec, name)
  File "C:\Users\ProstoChelovek\AppData\Local\Programs\Python\Python38-32\lib\site-packages\discord\ext\commands\bot.py", line 599, in _load_from_module_spec
    raise errors.ExtensionFailed(key, e) from e
discord.ext.commands.errors.ExtensionFailed: Extension 'Cogs.events' raised an error: ModuleNotFoundError: No module named 'moderate'

=============================================================

=============================================================
Время: 2020-07-12 11:51:40.744005

Ошибка:
Traceback (most recent call last):
  File "C:\Users\ProstoChelovek\AppData\Local\Programs\Python\Python38-32\lib\site-packages\discord\ext\commands\bot.py", line 596, in _load_from_module_spec
    spec.loader.exec_module(lib)
  File "<frozen importlib._bootstrap_external>", line 783, in exec_module
  File "<frozen importlib._bootstrap>", line 219, in _call_with_frames_removed
  File "E:\PyProg\ProstoTools(Original version)\Cogs\events.py", line 8, in <module>
    from moderate import Moderate
ModuleNotFoundError: No module named 'moderate'

The above exception was the direct cause of the following exception:

Traceback (most recent call last):
  File "bot.py", line 75, in <module>
    client.load_extension(f'Cogs.{filename[:-3]}')
  File "C:\Users\ProstoChelovek\AppData\Local\Programs\Python\Python38-32\lib\site-packages\discord\ext\commands\bot.py", line 653, in load_extension
    self._load_from_module_spec(spec, name)
  File "C:\Users\ProstoChelovek\AppData\Local\Programs\Python\Python38-32\lib\site-packages\discord\ext\commands\bot.py", line 599, in _load_from_module_spec
    raise errors.ExtensionFailed(key, e) from e
discord.ext.commands.errors.ExtensionFailed: Extension 'Cogs.events' raised an error: ModuleNotFoundError: No module named 'moderate'

=============================================================

=============================================================
Время: 2020-07-12 11:56:27.777739

Ошибка:
Traceback (most recent call last):
  File "C:\Users\ProstoChelovek\AppData\Local\Programs\Python\Python38-32\lib\site-packages\discord\ext\commands\bot.py", line 596, in _load_from_module_spec
    spec.loader.exec_module(lib)
  File "<frozen importlib._bootstrap_external>", line 779, in exec_module
  File "<frozen importlib._bootstrap_external>", line 916, in get_code
  File "<frozen importlib._bootstrap_external>", line 846, in source_to_code
  File "<frozen importlib._bootstrap>", line 219, in _call_with_frames_removed
  File "E:\PyProg\ProstoTools(Original version)\Cogs\events.py", line 400
    await Moderate.mute(self, message, message.author, 4, 'h', *, 'Авто-модерация:::Флуд')
                                                                ^
SyntaxError: invalid syntax

The above exception was the direct cause of the following exception:

Traceback (most recent call last):
  File "bot.py", line 75, in <module>
    client.load_extension(f'Cogs.{filename[:-3]}')
  File "C:\Users\ProstoChelovek\AppData\Local\Programs\Python\Python38-32\lib\site-packages\discord\ext\commands\bot.py", line 653, in load_extension
    self._load_from_module_spec(spec, name)
  File "C:\Users\ProstoChelovek\AppData\Local\Programs\Python\Python38-32\lib\site-packages\discord\ext\commands\bot.py", line 599, in _load_from_module_spec
    raise errors.ExtensionFailed(key, e) from e
discord.ext.commands.errors.ExtensionFailed: Extension 'Cogs.events' raised an error: SyntaxError: invalid syntax (events.py, line 400)

=============================================================

=============================================================
Время: 2020-07-12 11:47:35.606710

Ошибка:
Traceback (most recent call last):
  File "C:\Users\ProstoChelovek\AppData\Local\Programs\Python\Python38-32\lib\site-packages\discord\ext\commands\bot.py", line 596, in _load_from_module_spec
    spec.loader.exec_module(lib)
  File "<frozen importlib._bootstrap_external>", line 783, in exec_module
  File "<frozen importlib._bootstrap>", line 219, in _call_with_frames_removed
  File "E:\PyProg\ProstoTools(Original version)\Cogs\events.py", line 7, in <module>
    import moderate
ModuleNotFoundError: No module named 'moderate'

The above exception was the direct cause of the following exception:

Traceback (most recent call last):
  File "bot.py", line 75, in <module>
    client.load_extension(f'Cogs.{filename[:-3]}')
  File "C:\Users\ProstoChelovek\AppData\Local\Programs\Python\Python38-32\lib\site-packages\discord\ext\commands\bot.py", line 653, in load_extension
    self._load_from_module_spec(spec, name)
  File "C:\Users\ProstoChelovek\AppData\Local\Programs\Python\Python38-32\lib\site-packages\discord\ext\commands\bot.py", line 599, in _load_from_module_spec
    raise errors.ExtensionFailed(key, e) from e
discord.ext.commands.errors.ExtensionFailed: Extension 'Cogs.events' raised an error: ModuleNotFoundError: No module named 'moderate'

=============================================================

=============================================================
Время: 2020-07-12 11:51:40.744005

Ошибка:
Traceback (most recent call last):
  File "C:\Users\ProstoChelovek\AppData\Local\Programs\Python\Python38-32\lib\site-packages\discord\ext\commands\bot.py", line 596, in _load_from_module_spec
    spec.loader.exec_module(lib)
  File "<frozen importlib._bootstrap_external>", line 783, in exec_module
  File "<frozen importlib._bootstrap>", line 219, in _call_with_frames_removed
  File "E:\PyProg\ProstoTools(Original version)\Cogs\events.py", line 8, in <module>
    from moderate import Moderate
ModuleNotFoundError: No module named 'moderate'

The above exception was the direct cause of the following exception:

Traceback (most recent call last):
  File "bot.py", line 75, in <module>
    client.load_extension(f'Cogs.{filename[:-3]}')
  File "C:\Users\ProstoChelovek\AppData\Local\Programs\Python\Python38-32\lib\site-packages\discord\ext\commands\bot.py", line 653, in load_extension
    self._load_from_module_spec(spec, name)
  File "C:\Users\ProstoChelovek\AppData\Local\Programs\Python\Python38-32\lib\site-packages\discord\ext\commands\bot.py", line 599, in _load_from_module_spec
    raise errors.ExtensionFailed(key, e) from e
discord.ext.commands.errors.ExtensionFailed: Extension 'Cogs.events' raised an error: ModuleNotFoundError: No module named 'moderate'

=============================================================

=============================================================
Время: 2020-07-12 11:56:27.777739

Ошибка:
Traceback (most recent call last):
  File "C:\Users\ProstoChelovek\AppData\Local\Programs\Python\Python38-32\lib\site-packages\discord\ext\commands\bot.py", line 596, in _load_from_module_spec
    spec.loader.exec_module(lib)
  File "<frozen importlib._bootstrap_external>", line 779, in exec_module
  File "<frozen importlib._bootstrap_external>", line 916, in get_code
  File "<frozen importlib._bootstrap_external>", line 846, in source_to_code
  File "<frozen importlib._bootstrap>", line 219, in _call_with_frames_removed
  File "E:\PyProg\ProstoTools(Original version)\Cogs\events.py", line 400
    await Moderate.mute(self, message, message.author, 4, 'h', *, 'Авто-модерация:::Флуд')
                                                                ^
SyntaxError: invalid syntax

The above exception was the direct cause of the following exception:

Traceback (most recent call last):
  File "bot.py", line 75, in <module>
    client.load_extension(f'Cogs.{filename[:-3]}')
  File "C:\Users\ProstoChelovek\AppData\Local\Programs\Python\Python38-32\lib\site-packages\discord\ext\commands\bot.py", line 653, in load_extension
    self._load_from_module_spec(spec, name)
  File "C:\Users\ProstoChelovek\AppData\Local\Programs\Python\Python38-32\lib\site-packages\discord\ext\commands\bot.py", line 599, in _load_from_module_spec
    raise errors.ExtensionFailed(key, e) from e
discord.ext.commands.errors.ExtensionFailed: Extension 'Cogs.events' raised an error: SyntaxError: invalid syntax (events.py, line 400)

=============================================================

=============================================================
Время: 2020-07-12 12:18:49.867352

Ошибка:
Traceback (most recent call last):
  File "C:\Users\ProstoChelovek\AppData\Local\Programs\Python\Python38-32\lib\site-packages\discord\ext\commands\bot.py", line 596, in _load_from_module_spec
    spec.loader.exec_module(lib)
  File "<frozen importlib._bootstrap_external>", line 783, in exec_module
  File "<frozen importlib._bootstrap>", line 219, in _call_with_frames_removed
  File "E:\PyProg\ProstoTools(Original version)\Cogs\events.py", line 7, in <module>
    import Cogs.moderate
  File "E:\PyProg\ProstoTools(Original version)\Cogs\moderate.py", line 430
    async def mute( self = None, ctx, member: discord.Member, mute_time: int = 0, mute_typetime: str = None, *, reason = None ):
                    ^
SyntaxError: non-default argument follows default argument

The above exception was the direct cause of the following exception:

Traceback (most recent call last):
  File "bot.py", line 75, in <module>
    client.load_extension(f'Cogs.{filename[:-3]}')
  File "C:\Users\ProstoChelovek\AppData\Local\Programs\Python\Python38-32\lib\site-packages\discord\ext\commands\bot.py", line 653, in load_extension
    self._load_from_module_spec(spec, name)
  File "C:\Users\ProstoChelovek\AppData\Local\Programs\Python\Python38-32\lib\site-packages\discord\ext\commands\bot.py", line 599, in _load_from_module_spec
    raise errors.ExtensionFailed(key, e) from e
discord.ext.commands.errors.ExtensionFailed: Extension 'Cogs.events' raised an error: SyntaxError: non-default argument follows default argument (moderate.py, line 430)

=============================================================

=============================================================
Время: 2020-07-12 12:18:50.134636

Ошибка:
Traceback (most recent call last):
  File "C:\Users\ProstoChelovek\AppData\Local\Programs\Python\Python38-32\lib\site-packages\discord\ext\commands\bot.py", line 596, in _load_from_module_spec
    spec.loader.exec_module(lib)
  File "<frozen importlib._bootstrap_external>", line 779, in exec_module
  File "<frozen importlib._bootstrap_external>", line 916, in get_code
  File "<frozen importlib._bootstrap_external>", line 846, in source_to_code
  File "<frozen importlib._bootstrap>", line 219, in _call_with_frames_removed
  File "E:\PyProg\ProstoTools(Original version)\Cogs\moderate.py", line 430
    async def mute( self = None, ctx, member: discord.Member, mute_time: int = 0, mute_typetime: str = None, *, reason = None ):
                    ^
SyntaxError: non-default argument follows default argument

The above exception was the direct cause of the following exception:

Traceback (most recent call last):
  File "bot.py", line 75, in <module>
    client.load_extension(f'Cogs.{filename[:-3]}')
  File "C:\Users\ProstoChelovek\AppData\Local\Programs\Python\Python38-32\lib\site-packages\discord\ext\commands\bot.py", line 653, in load_extension
    self._load_from_module_spec(spec, name)
  File "C:\Users\ProstoChelovek\AppData\Local\Programs\Python\Python38-32\lib\site-packages\discord\ext\commands\bot.py", line 599, in _load_from_module_spec
    raise errors.ExtensionFailed(key, e) from e
discord.ext.commands.errors.ExtensionFailed: Extension 'Cogs.moderate' raised an error: SyntaxError: non-default argument follows default argument (moderate.py, line 430)

=============================================================

=============================================================
Время: 2020-07-12 12:35:28.550245

Ошибка:
Traceback (most recent call last):
  File "C:\Users\ProstoChelovek\AppData\Local\Programs\Python\Python38-32\lib\site-packages\discord\ext\commands\bot.py", line 596, in _load_from_module_spec
    spec.loader.exec_module(lib)
  File "<frozen importlib._bootstrap_external>", line 779, in exec_module
  File "<frozen importlib._bootstrap_external>", line 916, in get_code
  File "<frozen importlib._bootstrap_external>", line 846, in source_to_code
  File "<frozen importlib._bootstrap>", line 219, in _call_with_frames_removed
  File "E:\PyProg\ProstoTools(Original version)\Cogs\events.py", line 421
    if role if member.roles:
                           ^
SyntaxError: invalid syntax

The above exception was the direct cause of the following exception:

Traceback (most recent call last):
  File "bot.py", line 75, in <module>
    client.load_extension(f'Cogs.{filename[:-3]}')
  File "C:\Users\ProstoChelovek\AppData\Local\Programs\Python\Python38-32\lib\site-packages\discord\ext\commands\bot.py", line 653, in load_extension
    self._load_from_module_spec(spec, name)
  File "C:\Users\ProstoChelovek\AppData\Local\Programs\Python\Python38-32\lib\site-packages\discord\ext\commands\bot.py", line 599, in _load_from_module_spec
    raise errors.ExtensionFailed(key, e) from e
discord.ext.commands.errors.ExtensionFailed: Extension 'Cogs.events' raised an error: SyntaxError: invalid syntax (events.py, line 421)

=============================================================

=============================================================
Время: 2020-07-12 12:40:34.208508

Ошибка:
member is a required argument that is missing.
=============================================================

=============================================================
Время: 2020-07-12 12:40:41.446207

Ошибка:
Member "4" not found
=============================================================

=============================================================
Время: 2020-07-12 13:11:28.294877

Ошибка:
member is a required argument that is missing.
=============================================================

=============================================================
Время: 2020-07-12 13:15:06.090036

Ошибка:
member is a required argument that is missing.
=============================================================

=============================================================
Время: 2020-07-12 13:31:15.488327

Ошибка:
Command "server=info" is not found
=============================================================

=============================================================
Время: 2020-07-12 13:37:38.875108

Ошибка:
Command raised an exception: FileNotFoundError: [Errno 2] No such file or directory: './Data/Profiles/profile404224656598499348717776571406090310'
=============================================================

=============================================================
Время: 2020-07-12 13:38:29.922099

Ошибка:
Command raised an exception: FileNotFoundError: [Errno 2] No such file or directory: './Data/Profiles/profile204255221017214977679023516716367892'
=============================================================

=============================================================
Время: 2020-07-12 13:42:38.198396

Ошибка:
Command raised an exception: NameError: name 'guild' is not defined
=============================================================

=============================================================
Время: 2020-07-12 13:43:04.498106

Ошибка:
Command raised an exception: FileNotFoundError: [WinError 3] The system cannot find the path specified: './Data/Profiles/profile204255221017214977679023516716367892'
=============================================================

=============================================================
Время: 2020-07-12 13:44:03.486948

Ошибка:
Command raised an exception: UnboundLocalError: local variable 'dir_list' referenced before assignment
=============================================================

=============================================================
Время: 2020-07-12 14:04:42.109118

Ошибка:
Command raised an exception: UnboundLocalError: local variable 'mute_minutes' referenced before assignment
=============================================================

=============================================================
Время: 2020-07-12 14:06:13.993901

Ошибка:
Command raised an exception: IndexError: list index out of range
=============================================================

=============================================================
Время: 2020-07-12 14:25:24.801960

Ошибка:
Command raised an exception: NameError: name 'emb' is not defined
=============================================================

=============================================================
Время: 2020-07-12 15:13:19.109453

Ошибка:
Command raised an exception: HTTPException: 400 Bad Request (error code: 50006): Cannot send an empty message
=============================================================

=============================================================
Время: 2020-07-12 15:13:35.833362

Ошибка:
amount is a required argument that is missing.
=============================================================

=============================================================
Время: 2020-07-12 15:13:53.077180

Ошибка:
Command "clr" is not found
=============================================================

=============================================================
Время: 2020-07-12 16:25:06.547419

Ошибка:
Command raised an exception: NameError: name 'io' is not defined
=============================================================

=============================================================
Время: 2020-07-12 16:29:49.301765

Ошибка:
Command raised an exception: KeyError: 'КраСный'
=============================================================

=============================================================
Время: 2020-07-12 17:23:25.084011

Ошибка:
Command raised an exception: KeyError: None
=============================================================