

=============================================================
Время: 2020-08-13 20:30:34.045926

Ошибка:
Traceback (most recent call last):
  File "C:\Users\ProstoChelovek\AppData\Local\Programs\Python\Python38-32\lib\site-packages\discord\ext\commands\bot.py", line 596, in _load_from_module_spec
    spec.loader.exec_module(lib)
  File "<frozen importlib._bootstrap_external>", line 783, in exec_module
  File "<frozen importlib._bootstrap>", line 219, in _call_with_frames_removed
  File "e:\PyProg\ProstoTools\Bot\Cogs\errors.py", line 9, in <module>
    from configs import configs
ModuleNotFoundError: No module named 'configs'

The above exception was the direct cause of the following exception:

Traceback (most recent call last):
  File "e:\PyProg\ProstoTools\Bot\bot.py", line 60, in <module>
    client.load_extension(f'Bot.Cogs.{filename[:-3]}')
  File "C:\Users\ProstoChelovek\AppData\Local\Programs\Python\Python38-32\lib\site-packages\discord\ext\commands\bot.py", line 653, in load_extension
    self._load_from_module_spec(spec, name)
  File "C:\Users\ProstoChelovek\AppData\Local\Programs\Python\Python38-32\lib\site-packages\discord\ext\commands\bot.py", line 599, in _load_from_module_spec
    raise errors.ExtensionFailed(key, e) from e
discord.ext.commands.errors.ExtensionFailed: Extension 'Bot.Cogs.errors' raised an error: ModuleNotFoundError: No module named 'configs'

=============================================================

=============================================================
Время: 2020-08-13 20:30:34.081830

Ошибка:
Traceback (most recent call last):
  File "C:\Users\ProstoChelovek\AppData\Local\Programs\Python\Python38-32\lib\site-packages\discord\ext\commands\bot.py", line 596, in _load_from_module_spec
    spec.loader.exec_module(lib)
  File "<frozen importlib._bootstrap_external>", line 783, in exec_module
  File "<frozen importlib._bootstrap>", line 219, in _call_with_frames_removed
  File "e:\PyProg\ProstoTools\Bot\Cogs\events.py", line 10, in <module>
    from Tools.commands import Commands
ModuleNotFoundError: No module named 'Tools.commands'

The above exception was the direct cause of the following exception:

Traceback (most recent call last):
  File "e:\PyProg\ProstoTools\Bot\bot.py", line 60, in <module>
    client.load_extension(f'Bot.Cogs.{filename[:-3]}')
  File "C:\Users\ProstoChelovek\AppData\Local\Programs\Python\Python38-32\lib\site-packages\discord\ext\commands\bot.py", line 653, in load_extension
    self._load_from_module_spec(spec, name)
  File "C:\Users\ProstoChelovek\AppData\Local\Programs\Python\Python38-32\lib\site-packages\discord\ext\commands\bot.py", line 599, in _load_from_module_spec
    raise errors.ExtensionFailed(key, e) from e
discord.ext.commands.errors.ExtensionFailed: Extension 'Bot.Cogs.events' raised an error: ModuleNotFoundError: No module named 'Tools.commands'

=============================================================

=============================================================
Время: 2020-08-13 20:32:43.416147

Ошибка:
Traceback (most recent call last):
  File "C:\Users\ProstoChelovek\AppData\Local\Programs\Python\Python38-32\lib\site-packages\discord\ext\commands\bot.py", line 596, in _load_from_module_spec
    spec.loader.exec_module(lib)
  File "<frozen importlib._bootstrap_external>", line 783, in exec_module
  File "<frozen importlib._bootstrap>", line 219, in _call_with_frames_removed
  File "e:\PyProg\ProstoTools\Bot\Cogs\events.py", line 10, in <module>
    from Bot.Tools.commands import Commands
  File "e:\PyProg\ProstoTools\Bot\Tools\commands.py", line 8, in <module>
    from Tools.database import DB
ModuleNotFoundError: No module named 'Tools.database'

The above exception was the direct cause of the following exception:

Traceback (most recent call last):
  File "e:\PyProg\ProstoTools\Bot\bot.py", line 60, in <module>
    client.load_extension(f'Bot.Cogs.{filename[:-3]}')
  File "C:\Users\ProstoChelovek\AppData\Local\Programs\Python\Python38-32\lib\site-packages\discord\ext\commands\bot.py", line 653, in load_extension
    self._load_from_module_spec(spec, name)
  File "C:\Users\ProstoChelovek\AppData\Local\Programs\Python\Python38-32\lib\site-packages\discord\ext\commands\bot.py", line 599, in _load_from_module_spec
    raise errors.ExtensionFailed(key, e) from e
discord.ext.commands.errors.ExtensionFailed: Extension 'Bot.Cogs.events' raised an error: ModuleNotFoundError: No module named 'Tools.database'

=============================================================

=============================================================
Время: 2020-08-13 20:35:01.597991

Ошибка:
Traceback (most recent call last):
  File "C:\Users\ProstoChelovek\AppData\Local\Programs\Python\Python38-32\lib\site-packages\discord\ext\commands\bot.py", line 596, in _load_from_module_spec
    spec.loader.exec_module(lib)
  File "<frozen importlib._bootstrap_external>", line 783, in exec_module
  File "<frozen importlib._bootstrap>", line 219, in _call_with_frames_removed
  File "e:\PyProg\ProstoTools\Bot\Cogs\events.py", line 10, in <module>
    from Bot.Tools.commands import Commands
  File "e:\PyProg\ProstoTools\Bot\Tools\commands.py", line 8, in <module>
    from Tools.database import DB
ModuleNotFoundError: No module named 'Tools.database'

The above exception was the direct cause of the following exception:

Traceback (most recent call last):
  File "e:\PyProg\ProstoTools\Bot\bot.py", line 60, in <module>
    client.load_extension(f'Bot.Cogs.{filename[:-3]}')
  File "C:\Users\ProstoChelovek\AppData\Local\Programs\Python\Python38-32\lib\site-packages\discord\ext\commands\bot.py", line 653, in load_extension
    self._load_from_module_spec(spec, name)
  File "C:\Users\ProstoChelovek\AppData\Local\Programs\Python\Python38-32\lib\site-packages\discord\ext\commands\bot.py", line 599, in _load_from_module_spec
    raise errors.ExtensionFailed(key, e) from e
discord.ext.commands.errors.ExtensionFailed: Extension 'Bot.Cogs.events' raised an error: ModuleNotFoundError: No module named 'Tools.database'

=============================================================

=============================================================
Время: 2020-08-13 20:35:14.649542

Ошибка:
Traceback (most recent call last):
  File "C:\Users\ProstoChelovek\AppData\Local\Programs\Python\Python38-32\lib\site-packages\discord\ext\commands\bot.py", line 596, in _load_from_module_spec
    spec.loader.exec_module(lib)
  File "<frozen importlib._bootstrap_external>", line 783, in exec_module
  File "<frozen importlib._bootstrap>", line 219, in _call_with_frames_removed
  File "e:\PyProg\ProstoTools\Bot\Cogs\events.py", line 10, in <module>
    from Bot.Tools.commands import Commands
  File "e:\PyProg\ProstoTools\Bot\Tools\commands.py", line 8, in <module>
    from Tools.database import DB
ModuleNotFoundError: No module named 'Tools.database'

The above exception was the direct cause of the following exception:

Traceback (most recent call last):
  File "e:\PyProg\ProstoTools\Bot\bot.py", line 60, in <module>
    client.load_extension(f'Bot.Cogs.{filename[:-3]}')
  File "C:\Users\ProstoChelovek\AppData\Local\Programs\Python\Python38-32\lib\site-packages\discord\ext\commands\bot.py", line 653, in load_extension
    self._load_from_module_spec(spec, name)
  File "C:\Users\ProstoChelovek\AppData\Local\Programs\Python\Python38-32\lib\site-packages\discord\ext\commands\bot.py", line 599, in _load_from_module_spec
    raise errors.ExtensionFailed(key, e) from e
discord.ext.commands.errors.ExtensionFailed: Extension 'Bot.Cogs.events' raised an error: ModuleNotFoundError: No module named 'Tools.database'

=============================================================