

=============================================================
Время: 2020-10-10 10:58:53.421023

Ошибка:
Command raised an exception: UnboundLocalError: local variable 'mute_minutes' referenced before assignment
=============================================================

=============================================================
Время: 2020-10-10 11:18:00.575925

Ошибка:
Traceback (most recent call last):
  File "C:\Users\ProstoChelovek\AppData\Local\Programs\Python\Python38-32\lib\site-packages\discord\ext\commands\bot.py", line 607, in _load_from_module_spec
    spec.loader.exec_module(lib)
  File "<frozen importlib._bootstrap_external>", line 783, in exec_module
  File "<frozen importlib._bootstrap>", line 219, in _call_with_frames_removed
  File "e:\PyProg\ProstoTools\Cogs\utils.py", line 39, in <module>
    self.FOOTER = configs['FOOTER_TEXT']
NameError: name 'self' is not defined

The above exception was the direct cause of the following exception:

Traceback (most recent call last):
  File "e:/PyProg/ProstoTools/bot.py", line 58, in <module>
    client.load_extension(f'Cogs.{filename[:-3]}')
  File "C:\Users\ProstoChelovek\AppData\Local\Programs\Python\Python38-32\lib\site-packages\discord\ext\commands\bot.py", line 664, in load_extension
    self._load_from_module_spec(spec, name)
  File "C:\Users\ProstoChelovek\AppData\Local\Programs\Python\Python38-32\lib\site-packages\discord\ext\commands\bot.py", line 610, in _load_from_module_spec
    raise errors.ExtensionFailed(key, e) from e
discord.ext.commands.errors.ExtensionFailed: Extension 'Cogs.utils' raised an error: NameError: name 'self' is not defined

=============================================================