

=============================================================
Время: 2020-08-04 16:45:07.477495

Ошибка:
Command "list-moderates" is not found
=============================================================

=============================================================
Время: 2020-08-04 16:45:20.865638

Ошибка:
Command "list-moderators" is not found
=============================================================

=============================================================
Время: 2020-08-04 16:45:29.673599

Ошибка:
Command raised an exception: TypeError: sequence item 0: expected str instance, int found
=============================================================

=============================================================
Время: 2020-08-04 16:46:51.056053

Ошибка:
Command raised an exception: TypeError: sequence item 0: expected str instance, int found
=============================================================

=============================================================
Время: 2020-08-04 16:51:48.105282

Ошибка:
Command raised an exception: TypeError: can only concatenate str (not "NoneType") to str
=============================================================

=============================================================
Время: 2020-08-04 16:52:38.056221

Ошибка:
Command raised an exception: UnboundLocalError: local variable 'emb' referenced before assignment
=============================================================

=============================================================
Время: 2020-08-04 16:53:31.501768

Ошибка:
Command raised an exception: HTTPException: 400 Bad Request (error code: 50035): Invalid Form Body
In embed.fields.0.value: This field is required
In embed.fields.1.value: This field is required
In embed.fields.10.value: This field is required
In embed.fields.11.value: This field is required
In embed.fields.12.value: This field is required
In embed.fields.13.value: This field is required
In embed.fields.14.value: This field is required
In embed.fields.15.value: This field is required
In embed.fields.2.value: This field is required
In embed.fields.3.value: This field is required
In embed.fields.4.value: This field is required
In embed.fields.5.value: This field is required
In embed.fields.6.value: This field is required
In embed.fields.7.value: This field is required
In embed.fields.8.value: This field is required
In embed.fields.9.value: This field is required
=============================================================

=============================================================
Время: 2020-08-04 20:13:28.911328

Ошибка:
Traceback (most recent call last):
  File "C:\Users\ProstoChelovek\AppData\Local\Programs\Python\Python38-32\lib\site-packages\discord\ext\commands\bot.py", line 608, in _load_from_module_spec
    setup(self)
  File "E:\PyProg\ProstoTools\Cogs\economy.py", line 2013, in setup
    client.add_cog(Economy(client))
  File "C:\Users\ProstoChelovek\AppData\Local\Programs\Python\Python38-32\lib\site-packages\discord\ext\commands\bot.py", line 502, in add_cog
    cog = cog._inject(self)
  File "C:\Users\ProstoChelovek\AppData\Local\Programs\Python\Python38-32\lib\site-packages\discord\ext\commands\cog.py", line 379, in _inject
    raise e
  File "C:\Users\ProstoChelovek\AppData\Local\Programs\Python\Python38-32\lib\site-packages\discord\ext\commands\cog.py", line 374, in _inject
    bot.add_command(command)
  File "C:\Users\ProstoChelovek\AppData\Local\Programs\Python\Python38-32\lib\site-packages\discord\ext\commands\core.py", line 1076, in add_command
    raise discord.ClientException('The alias {} is already an existing command or alias.'.format(alias))
discord.errors.ClientException: The alias +rep is already an existing command or alias.

The above exception was the direct cause of the following exception:

Traceback (most recent call last):
  File "bot.py", line 60, in <module>
    client.load_extension(f'Cogs.{filename[:-3]}')
  File "C:\Users\ProstoChelovek\AppData\Local\Programs\Python\Python38-32\lib\site-packages\discord\ext\commands\bot.py", line 653, in load_extension
    self._load_from_module_spec(spec, name)
  File "C:\Users\ProstoChelovek\AppData\Local\Programs\Python\Python38-32\lib\site-packages\discord\ext\commands\bot.py", line 613, in _load_from_module_spec
    raise errors.ExtensionFailed(key, e) from e
discord.ext.commands.errors.ExtensionFailed: Extension 'Cogs.economy' raised an error: ClientException: The alias +rep is already an existing command or alias.

=============================================================

=============================================================
Время: 2020-08-04 20:15:45.222996

Ошибка:
Traceback (most recent call last):
  File "C:\Users\ProstoChelovek\AppData\Local\Programs\Python\Python38-32\lib\site-packages\discord\ext\commands\bot.py", line 608, in _load_from_module_spec
    setup(self)
  File "E:\PyProg\ProstoTools\Cogs\economy.py", line 2013, in setup
    client.add_cog(Economy(client))
  File "C:\Users\ProstoChelovek\AppData\Local\Programs\Python\Python38-32\lib\site-packages\discord\ext\commands\bot.py", line 502, in add_cog
    cog = cog._inject(self)
  File "C:\Users\ProstoChelovek\AppData\Local\Programs\Python\Python38-32\lib\site-packages\discord\ext\commands\cog.py", line 379, in _inject
    raise e
  File "C:\Users\ProstoChelovek\AppData\Local\Programs\Python\Python38-32\lib\site-packages\discord\ext\commands\cog.py", line 374, in _inject
    bot.add_command(command)
  File "C:\Users\ProstoChelovek\AppData\Local\Programs\Python\Python38-32\lib\site-packages\discord\ext\commands\core.py", line 1076, in add_command
    raise discord.ClientException('The alias {} is already an existing command or alias.'.format(alias))
discord.errors.ClientException: The alias +rep is already an existing command or alias.

The above exception was the direct cause of the following exception:

Traceback (most recent call last):
  File "bot.py", line 60, in <module>
    client.load_extension(f'Cogs.{filename[:-3]}')
  File "C:\Users\ProstoChelovek\AppData\Local\Programs\Python\Python38-32\lib\site-packages\discord\ext\commands\bot.py", line 653, in load_extension
    self._load_from_module_spec(spec, name)
  File "C:\Users\ProstoChelovek\AppData\Local\Programs\Python\Python38-32\lib\site-packages\discord\ext\commands\bot.py", line 613, in _load_from_module_spec
    raise errors.ExtensionFailed(key, e) from e
discord.ext.commands.errors.ExtensionFailed: Extension 'Cogs.economy' raised an error: ClientException: The alias +rep is already an existing command or alias.

=============================================================

=============================================================
Время: 2020-08-04 20:16:21.127299

Ошибка:
Traceback (most recent call last):
  File "C:\Users\ProstoChelovek\AppData\Local\Programs\Python\Python38-32\lib\site-packages\discord\ext\commands\bot.py", line 608, in _load_from_module_spec
    setup(self)
  File "E:\PyProg\ProstoTools\Cogs\economy.py", line 2013, in setup
    client.add_cog(Economy(client))
  File "C:\Users\ProstoChelovek\AppData\Local\Programs\Python\Python38-32\lib\site-packages\discord\ext\commands\bot.py", line 502, in add_cog
    cog = cog._inject(self)
  File "C:\Users\ProstoChelovek\AppData\Local\Programs\Python\Python38-32\lib\site-packages\discord\ext\commands\cog.py", line 379, in _inject
    raise e
  File "C:\Users\ProstoChelovek\AppData\Local\Programs\Python\Python38-32\lib\site-packages\discord\ext\commands\cog.py", line 374, in _inject
    bot.add_command(command)
  File "C:\Users\ProstoChelovek\AppData\Local\Programs\Python\Python38-32\lib\site-packages\discord\ext\commands\core.py", line 1076, in add_command
    raise discord.ClientException('The alias {} is already an existing command or alias.'.format(alias))
discord.errors.ClientException: The alias +rep is already an existing command or alias.

The above exception was the direct cause of the following exception:

Traceback (most recent call last):
  File "bot.py", line 60, in <module>
    client.load_extension(f'Cogs.{filename[:-3]}')
  File "C:\Users\ProstoChelovek\AppData\Local\Programs\Python\Python38-32\lib\site-packages\discord\ext\commands\bot.py", line 653, in load_extension
    self._load_from_module_spec(spec, name)
  File "C:\Users\ProstoChelovek\AppData\Local\Programs\Python\Python38-32\lib\site-packages\discord\ext\commands\bot.py", line 613, in _load_from_module_spec
    raise errors.ExtensionFailed(key, e) from e
discord.ext.commands.errors.ExtensionFailed: Extension 'Cogs.economy' raised an error: ClientException: The alias +rep is already an existing command or alias.

=============================================================

=============================================================
Время: 2020-08-04 20:16:25.121492

Ошибка:
Command raised an exception: AttributeError: 'mappingproxy' object has no attribute 'name'
=============================================================

=============================================================
Время: 2020-08-04 20:18:44.464576

Ошибка:
Traceback (most recent call last):
  File "C:\Users\ProstoChelovek\AppData\Local\Programs\Python\Python38-32\lib\site-packages\discord\ext\commands\bot.py", line 608, in _load_from_module_spec
    setup(self)
  File "E:\PyProg\ProstoTools\Cogs\economy.py", line 2013, in setup
    client.add_cog(Economy(client))
  File "C:\Users\ProstoChelovek\AppData\Local\Programs\Python\Python38-32\lib\site-packages\discord\ext\commands\bot.py", line 502, in add_cog
    cog = cog._inject(self)
  File "C:\Users\ProstoChelovek\AppData\Local\Programs\Python\Python38-32\lib\site-packages\discord\ext\commands\cog.py", line 379, in _inject
    raise e
  File "C:\Users\ProstoChelovek\AppData\Local\Programs\Python\Python38-32\lib\site-packages\discord\ext\commands\cog.py", line 374, in _inject
    bot.add_command(command)
  File "C:\Users\ProstoChelovek\AppData\Local\Programs\Python\Python38-32\lib\site-packages\discord\ext\commands\core.py", line 1076, in add_command
    raise discord.ClientException('The alias {} is already an existing command or alias.'.format(alias))
discord.errors.ClientException: The alias +rep is already an existing command or alias.

The above exception was the direct cause of the following exception:

Traceback (most recent call last):
  File "bot.py", line 60, in <module>
    client.load_extension(f'Cogs.{filename[:-3]}')
  File "C:\Users\ProstoChelovek\AppData\Local\Programs\Python\Python38-32\lib\site-packages\discord\ext\commands\bot.py", line 653, in load_extension
    self._load_from_module_spec(spec, name)
  File "C:\Users\ProstoChelovek\AppData\Local\Programs\Python\Python38-32\lib\site-packages\discord\ext\commands\bot.py", line 613, in _load_from_module_spec
    raise errors.ExtensionFailed(key, e) from e
discord.ext.commands.errors.ExtensionFailed: Extension 'Cogs.economy' raised an error: ClientException: The alias +rep is already an existing command or alias.

=============================================================

=============================================================
Время: 2020-08-04 20:18:50.690433

Ошибка:
Command raised an exception: AttributeError: 'str' object has no attribute 'name'
=============================================================

=============================================================
Время: 2020-08-04 20:21:38.432086

Ошибка:
Traceback (most recent call last):
  File "C:\Users\ProstoChelovek\AppData\Local\Programs\Python\Python38-32\lib\site-packages\discord\ext\commands\bot.py", line 608, in _load_from_module_spec
    setup(self)
  File "E:\PyProg\ProstoTools\Cogs\economy.py", line 2013, in setup
    client.add_cog(Economy(client))
  File "C:\Users\ProstoChelovek\AppData\Local\Programs\Python\Python38-32\lib\site-packages\discord\ext\commands\bot.py", line 502, in add_cog
    cog = cog._inject(self)
  File "C:\Users\ProstoChelovek\AppData\Local\Programs\Python\Python38-32\lib\site-packages\discord\ext\commands\cog.py", line 379, in _inject
    raise e
  File "C:\Users\ProstoChelovek\AppData\Local\Programs\Python\Python38-32\lib\site-packages\discord\ext\commands\cog.py", line 374, in _inject
    bot.add_command(command)
  File "C:\Users\ProstoChelovek\AppData\Local\Programs\Python\Python38-32\lib\site-packages\discord\ext\commands\core.py", line 1076, in add_command
    raise discord.ClientException('The alias {} is already an existing command or alias.'.format(alias))
discord.errors.ClientException: The alias +rep is already an existing command or alias.

The above exception was the direct cause of the following exception:

Traceback (most recent call last):
  File "bot.py", line 60, in <module>
    client.load_extension(f'Cogs.{filename[:-3]}')
  File "C:\Users\ProstoChelovek\AppData\Local\Programs\Python\Python38-32\lib\site-packages\discord\ext\commands\bot.py", line 653, in load_extension
    self._load_from_module_spec(spec, name)
  File "C:\Users\ProstoChelovek\AppData\Local\Programs\Python\Python38-32\lib\site-packages\discord\ext\commands\bot.py", line 613, in _load_from_module_spec
    raise errors.ExtensionFailed(key, e) from e
discord.ext.commands.errors.ExtensionFailed: Extension 'Cogs.economy' raised an error: ClientException: The alias +rep is already an existing command or alias.

=============================================================

=============================================================
Время: 2020-08-04 20:21:45.567379

Ошибка:
Command raised an exception: TypeError: get() takes 1 positional argument but 2 were given
=============================================================

=============================================================
Время: 2020-08-04 20:22:05.608570

Ошибка:
Traceback (most recent call last):
  File "C:\Users\ProstoChelovek\AppData\Local\Programs\Python\Python38-32\lib\site-packages\discord\ext\commands\bot.py", line 608, in _load_from_module_spec
    setup(self)
  File "E:\PyProg\ProstoTools\Cogs\economy.py", line 2013, in setup
    client.add_cog(Economy(client))
  File "C:\Users\ProstoChelovek\AppData\Local\Programs\Python\Python38-32\lib\site-packages\discord\ext\commands\bot.py", line 502, in add_cog
    cog = cog._inject(self)
  File "C:\Users\ProstoChelovek\AppData\Local\Programs\Python\Python38-32\lib\site-packages\discord\ext\commands\cog.py", line 379, in _inject
    raise e
  File "C:\Users\ProstoChelovek\AppData\Local\Programs\Python\Python38-32\lib\site-packages\discord\ext\commands\cog.py", line 374, in _inject
    bot.add_command(command)
  File "C:\Users\ProstoChelovek\AppData\Local\Programs\Python\Python38-32\lib\site-packages\discord\ext\commands\core.py", line 1076, in add_command
    raise discord.ClientException('The alias {} is already an existing command or alias.'.format(alias))
discord.errors.ClientException: The alias +rep is already an existing command or alias.

The above exception was the direct cause of the following exception:

Traceback (most recent call last):
  File "bot.py", line 60, in <module>
    client.load_extension(f'Cogs.{filename[:-3]}')
  File "C:\Users\ProstoChelovek\AppData\Local\Programs\Python\Python38-32\lib\site-packages\discord\ext\commands\bot.py", line 653, in load_extension
    self._load_from_module_spec(spec, name)
  File "C:\Users\ProstoChelovek\AppData\Local\Programs\Python\Python38-32\lib\site-packages\discord\ext\commands\bot.py", line 613, in _load_from_module_spec
    raise errors.ExtensionFailed(key, e) from e
discord.ext.commands.errors.ExtensionFailed: Extension 'Cogs.economy' raised an error: ClientException: The alias +rep is already an existing command or alias.

=============================================================

=============================================================
Время: 2020-08-04 20:22:10.883180

Ошибка:
Command raised an exception: AttributeError: 'str' object has no attribute 'name'
=============================================================

=============================================================
Время: 2020-08-04 20:23:09.190227

Ошибка:
Traceback (most recent call last):
  File "C:\Users\ProstoChelovek\AppData\Local\Programs\Python\Python38-32\lib\site-packages\discord\ext\commands\bot.py", line 608, in _load_from_module_spec
    setup(self)
  File "E:\PyProg\ProstoTools\Cogs\economy.py", line 2013, in setup
    client.add_cog(Economy(client))
  File "C:\Users\ProstoChelovek\AppData\Local\Programs\Python\Python38-32\lib\site-packages\discord\ext\commands\bot.py", line 502, in add_cog
    cog = cog._inject(self)
  File "C:\Users\ProstoChelovek\AppData\Local\Programs\Python\Python38-32\lib\site-packages\discord\ext\commands\cog.py", line 379, in _inject
    raise e
  File "C:\Users\ProstoChelovek\AppData\Local\Programs\Python\Python38-32\lib\site-packages\discord\ext\commands\cog.py", line 374, in _inject
    bot.add_command(command)
  File "C:\Users\ProstoChelovek\AppData\Local\Programs\Python\Python38-32\lib\site-packages\discord\ext\commands\core.py", line 1076, in add_command
    raise discord.ClientException('The alias {} is already an existing command or alias.'.format(alias))
discord.errors.ClientException: The alias +rep is already an existing command or alias.

The above exception was the direct cause of the following exception:

Traceback (most recent call last):
  File "bot.py", line 60, in <module>
    client.load_extension(f'Cogs.{filename[:-3]}')
  File "C:\Users\ProstoChelovek\AppData\Local\Programs\Python\Python38-32\lib\site-packages\discord\ext\commands\bot.py", line 653, in load_extension
    self._load_from_module_spec(spec, name)
  File "C:\Users\ProstoChelovek\AppData\Local\Programs\Python\Python38-32\lib\site-packages\discord\ext\commands\bot.py", line 613, in _load_from_module_spec
    raise errors.ExtensionFailed(key, e) from e
discord.ext.commands.errors.ExtensionFailed: Extension 'Cogs.economy' raised an error: ClientException: The alias +rep is already an existing command or alias.

=============================================================

=============================================================
Время: 2020-08-04 20:23:13.633165

Ошибка:
Command raised an exception: AttributeError: 'Different' object has no attribute 'name'
=============================================================

=============================================================
Время: 2020-08-04 20:24:03.729826

Ошибка:
Traceback (most recent call last):
  File "C:\Users\ProstoChelovek\AppData\Local\Programs\Python\Python38-32\lib\site-packages\discord\ext\commands\bot.py", line 608, in _load_from_module_spec
    setup(self)
  File "E:\PyProg\ProstoTools\Cogs\economy.py", line 2013, in setup
    client.add_cog(Economy(client))
  File "C:\Users\ProstoChelovek\AppData\Local\Programs\Python\Python38-32\lib\site-packages\discord\ext\commands\bot.py", line 502, in add_cog
    cog = cog._inject(self)
  File "C:\Users\ProstoChelovek\AppData\Local\Programs\Python\Python38-32\lib\site-packages\discord\ext\commands\cog.py", line 379, in _inject
    raise e
  File "C:\Users\ProstoChelovek\AppData\Local\Programs\Python\Python38-32\lib\site-packages\discord\ext\commands\cog.py", line 374, in _inject
    bot.add_command(command)
  File "C:\Users\ProstoChelovek\AppData\Local\Programs\Python\Python38-32\lib\site-packages\discord\ext\commands\core.py", line 1076, in add_command
    raise discord.ClientException('The alias {} is already an existing command or alias.'.format(alias))
discord.errors.ClientException: The alias +rep is already an existing command or alias.

The above exception was the direct cause of the following exception:

Traceback (most recent call last):
  File "bot.py", line 60, in <module>
    client.load_extension(f'Cogs.{filename[:-3]}')
  File "C:\Users\ProstoChelovek\AppData\Local\Programs\Python\Python38-32\lib\site-packages\discord\ext\commands\bot.py", line 653, in load_extension
    self._load_from_module_spec(spec, name)
  File "C:\Users\ProstoChelovek\AppData\Local\Programs\Python\Python38-32\lib\site-packages\discord\ext\commands\bot.py", line 613, in _load_from_module_spec
    raise errors.ExtensionFailed(key, e) from e
discord.ext.commands.errors.ExtensionFailed: Extension 'Cogs.economy' raised an error: ClientException: The alias +rep is already an existing command or alias.

=============================================================

=============================================================
Время: 2020-08-04 20:24:07.292298

Ошибка:
Command raised an exception: TypeError: sequence item 0: expected str instance, Different found
=============================================================

=============================================================
Время: 2020-08-04 20:25:51.445879

Ошибка:
Traceback (most recent call last):
  File "C:\Users\ProstoChelovek\AppData\Local\Programs\Python\Python38-32\lib\site-packages\discord\ext\commands\bot.py", line 608, in _load_from_module_spec
    setup(self)
  File "E:\PyProg\ProstoTools\Cogs\economy.py", line 2013, in setup
    client.add_cog(Economy(client))
  File "C:\Users\ProstoChelovek\AppData\Local\Programs\Python\Python38-32\lib\site-packages\discord\ext\commands\bot.py", line 502, in add_cog
    cog = cog._inject(self)
  File "C:\Users\ProstoChelovek\AppData\Local\Programs\Python\Python38-32\lib\site-packages\discord\ext\commands\cog.py", line 379, in _inject
    raise e
  File "C:\Users\ProstoChelovek\AppData\Local\Programs\Python\Python38-32\lib\site-packages\discord\ext\commands\cog.py", line 374, in _inject
    bot.add_command(command)
  File "C:\Users\ProstoChelovek\AppData\Local\Programs\Python\Python38-32\lib\site-packages\discord\ext\commands\core.py", line 1076, in add_command
    raise discord.ClientException('The alias {} is already an existing command or alias.'.format(alias))
discord.errors.ClientException: The alias +rep is already an existing command or alias.

The above exception was the direct cause of the following exception:

Traceback (most recent call last):
  File "bot.py", line 60, in <module>
    client.load_extension(f'Cogs.{filename[:-3]}')
  File "C:\Users\ProstoChelovek\AppData\Local\Programs\Python\Python38-32\lib\site-packages\discord\ext\commands\bot.py", line 653, in load_extension
    self._load_from_module_spec(spec, name)
  File "C:\Users\ProstoChelovek\AppData\Local\Programs\Python\Python38-32\lib\site-packages\discord\ext\commands\bot.py", line 613, in _load_from_module_spec
    raise errors.ExtensionFailed(key, e) from e
discord.ext.commands.errors.ExtensionFailed: Extension 'Cogs.economy' raised an error: ClientException: The alias +rep is already an existing command or alias.

=============================================================

=============================================================
Время: 2020-08-04 20:28:44.893172

Ошибка:
Command raised an exception: AttributeError: 'Different' object has no attribute 'name'
=============================================================

=============================================================
Время: 2020-08-04 20:29:51.243686

Ошибка:
Command raised an exception: NameError: name 'cogs' is not defined
=============================================================

=============================================================
Время: 2020-08-04 21:29:23.989769

Ошибка:
Command raised an exception: TypeError: 'NoneType' object is not subscriptable
=============================================================